Workbook

Sheet 通讯通路门店
A1: 位置信息 | E1: 门店信息 | R1: 客户信息 | T1: 分价位段销量统计/台 （只填数字即可，不加单位） | W1: 分品牌销量统计/台 （只填数字即可，不加单位） | AC1: 门店全场景销量/台 （只填数字即可，不加单位） | AJ1: 分品牌阵地、门头、位置信息统计 | BB1: 各品牌促销员数量/个 （只填数字即可，不加单位） | BJ1: 其他信息
A2: 省份中文名称 | B2: 城市中文名称 | C2: 区县中文名称 | D2: 乡镇中文名称 | E2: 门店规划进度 | F2: 门店编码 | G2: 门店名称 | H2: 地理编码 | I2: 商圈编码 | J2: 门店类型 | K2: 门店capa | L2: 门店面积（㎡） | M2: 门店经营状态 | N2: 运营商类型 | O2: 门店联系人 | P2: 门店联系方式 | Q2: 门店地址 | R2: 渠道编码 | S2: 客户名称（未合作以营业执照为准、已合作以客户A名为准） | T2: 手机价格-0-2500元 | U2: 手机价格2500-4000元 | V2: 手机价格-＞4000元 | W2: 荣耀手机销量 | X2: 华为手机销量 | Y2: 小米手机销量 | Z2: VIVO手机销量 | AA2: 苹果手机销量 | AB2: OPPO手机销量 | AC2: 荣耀PC销量 | AD2: 华为PC销量 | AE2: 荣耀平板销量 | AF2: 华为平板销量 | AG2: PC销量 | AH2: 平板销量 | AI2: 手表销量 | AJ2: 荣耀阵地数量 | AK2: 荣耀阵地位置 | AL2: 荣耀门头数量 | AM2: 华为阵地数量 | AN2: 华为阵地位置 | AO2: 华为门头数量 | AP2: 小米阵地数量 | AQ2: 小米阵地位置 | AR2: 小米门头数量 | AS2: VIVO阵地数量 | AT2: VIVO阵地位置 | AU2: VIVO门头数量 | AV2: 苹果阵地数量 | AW2: 苹果阵地位置 | AX2: 苹果门头数量 | AY2: OPPO阵地数量 | AZ2: OPPO阵地位置 | BA2: OPPO门头数量 | BB2: 荣耀促销员数量 | BC2: 华为促销员数量 | BD2: 小米促销员数量 | BE2: VIVO促销员数量 | BF2: 苹果促销员数量 | BG2: OPPO促销员数量 | BH2: 客户店员 | BI2: 店端人数总和 | BJ2: 是否国补门店 | BK2: 门店城乡类别 | BL2: 是否街边店/MALL店 | BM2: 备注
A3: 如： 四川省 | B3: 如： 成都市 | C3: 如： 青羊区 龙泉驿区 简阳市 | D3: 如： 洛带镇 洪安镇 | E3: 已存在：在微服务系统中已录入的门店 无规划：不在荣耀系统的门店，不合作门店 洽谈中：不在荣耀系统的门店，规划合作门店 | F3: 1、已在荣耀系统注册填写编码（字母开头） 2、未在荣耀系统注册，已存在 沙盘系统编码（6开头） 3、未在沙盘及荣耀系统，填写“洽谈中”,“无规划“ | G3: 编码对应的门店名称，如未导入门店按照门店命名规则命名 命名规则（不含”市“&”区“）：地市+区/县+客户简称+所在道路名/所在公示商圈+点名/营业厅；例如重庆开州耀琪龙新天地电信营业厅 | H3: 见 sheet“地理信息 | I3: 见 sheet“商圈信息 | J3: 1、加入”NKA综合卖场“标签，如对应为NKA开的体验店，应填体验店；NKA指：国苏迪+京东之家+五星+居然之家+信联和+中免； 2、华为堡垒店归类为专卖店；归为综合卖场还是专卖店主要是看能否售卖其他品牌。华为销服一体店如果不能卖其他品牌的话，算华为授权店 3、运营商厅店类型：限于电信核心厅店，移动泛全联盟厅店，联通厅店，和运营商组对齐名单 综合卖场/荣耀体验店/荣耀授权专卖店/耀生活独立店/华为授权体验店/华为堡垒店/华为非授权店/OPPO体验店/VIVO体验店/小米体验店/苹果体验店/其他品牌专卖店/运营商厅店/NKA综合卖场/其他 | K3: 填写门店真实零售capa（不含分销/团单等），单位：台，数量为整数 | L3: 门店面积，单位㎡ | M3: 拉通微服务，内容4项 不合作/营业中/闭店/装修中 | N3: 门店的运营商属性，填“公开/公开&三网/排它-移动/排它-电信/排它-联通/非排它-移动电信/非排它-移动联通/非排它-电信联通” | O3: 门店责任人：张三（示例） | P3: 联系方式：1xxxxxxxxx | Q3: 精确到省、市、县区/乡镇、街道 | R3: 客户在PSI系统中的Channel ID®，如：100016798101，如不涉及填“无” | S3: 客户在PSI系统中的Account Name®，如：四川佳海电子有限公司，如不在系统中则填写客户正式名称，不可为空 | T3: 必填,取值0-999999 不含分销和团单，所有门店均需填写 | U3: 必填,取值0-999999 不含分销和团单，所有门店均需填写 | V3: 必填,取值0-999999 不含分销和团单，所有门店均需填写 | W3: 价位段销量求和与品牌销量求和需相等 | X3: 含智选等 价位段销量求和与品牌销量求和需相等 | Y3: 价位段销量求和与品牌销量求和需相等 | Z3: iQOO归入vivo 价位段销量求和与品牌销量求和需相等 | AA3: 价位段销量求和与品牌销量求和需相等 | AB3: realme归入oppo 价位段销量求和与品牌销量求和需相等 | AC3: 必填,取值0-999999 不含分销和团单，所有门店均需填写 | AD3: 必填,取值0-999999 不含分销和团单，所有门店均需填写 | AE3: 必填,取值0-999999 不含分销和团单，所有门店均需填写 | AF3: 必填,取值0-999999 不含分销和团单，所有门店均需填写 | AG3: 必填,取值0-999999 不含分销和团单，所有门店均需填写 | AH3: 必填,取值0-999999 不含分销和团单，所有门店均需填写 | AI3: 必填,取值0-999999 不含分销和团单，所有门店均需填写 | AJ3: 单位：套 | AK3: TOP1/TOP2/TOP3/其他 TOP位为唯一 | AL3: 单位：个 | AM3: 单位：套 | AN3: TOP1/TOP2/TOP3/其他 TOP位为唯一 | AO3: 单位：个 | AP3: 单位：套 | AQ3: TOP1/TOP2/TOP3/其他 TOP位为唯一 | AR3: 单位：个 | AS3: 单位：套 | AT3: TOP1/TOP2/TOP3/其他 TOP位为唯一 | AU3: 单位：个 | AV3: 单位：套 | AW3: TOP1/TOP2/TOP3/其他 TOP位为唯一 | AX3: 单位：个 | AY3: 单位：套 | AZ3: TOP1/TOP2/TOP3/其他 TOP位为唯一 | BA3: 单位：个 | BB3: 单位：人 | BC3: 单位：人 | BD3: 单位：人 | BE3: VIVO厂家促销员+返聘数量，单位：人 | BF3: 单位：人 | BG3: OPPO厂家促销员+返聘数量，单位：人 | BH3: 单位：人 | BI3: 单位：人 | BJ3: 是/否 | BK3: 如： 主城区 非主城区 | BL3: 如： 街边店 MALL店 | BM3: /
A4: 海南省 | B4: 东方市 | C4: 东方市 | D4: 大田镇 | E4: 已存在 | F4: RYCM08980062 | G4: 东方大田巨为零公里移动营业营 | H4: 55014111 | I4: CNSQCN00054156 | J4: 综合卖场 | K4: =SUM(T4:AI4) -> 145 | M4: 营业中 | N4: 排它-移动 | O4: 符重鹏 | P4: 15109896206 | Q4: 海南省东方市大田镇海榆西线零公里路口东河镇方向 | R4: 200018297501 | S4: 东方八所巨为手机连锁店 | T4: 58 | U4: 15 | V4: 0 | W4: 12 | X4: 0 | Y4: 3 | Z4: 22 | AA4: 0 | AB4: 35 | AC4: 0 | AD4: 0 | AE4: 0 | AF4: 0 | AG4: 0 | AH4: 0 | AI4: 0 | AJ4: 1 | AK4: TOP3 | AL4: 0 | AM4: 1 | AN4: 其他 | AO4: 0 | AP4: 1 | AQ4: 其他 | AR4: 0 | AS4: 0 | AT4: 其他 | AU4: 0 | AV4: 0 | AW4: 其他 | AX4: 0 | AY4: 0 | AZ4: 其他 | BA4: 0 | BB4: 0 | BC4: 0 | BD4: 0 | BE4: 1 | BF4: 0 | BG4: 0 | BH4: 2 | BI4: 3 | BJ4: 是 | BK4: 非主城区 | BL4: 街边店
A5: 海南省 | B5: 东方市 | C5: 东方市 | D5: 八所镇 | E5: 已存在 | F5: CNSCN323252 | G5: 东方华商万达广场体验店 | H5: 55014109 | I5: CNSQCN00054154 | J5: 荣耀体验店 | K5: =SUM(T5:AI5) -> 145 | M5: 营业中 | N5: 公开 | O5: 王发丽 | P5: 18789551848 | Q5: 海南东⽅市八所镇解放东路与感恩南路交汇处万达⼴场1楼1031 | R5: 200002521201 | S5: 海南华商智能科技有限公司 | T5: 12 | U5: 35 | V5: 20 | W5: 67 | X5: 0 | Y5: 0 | Z5: 0 | AA5: 0 | AB5: 0 | AC5: 1 | AD5: 0 | AE5: 3 | AF5: 0 | AG5: 1 | AH5: 3 | AI5: 3 | AJ5: 1 | AK5: TOP1 | AL5: 0 | AM5: 0 | AN5: 其他 | AO5: 0 | AP5: 0 | AQ5: 其他 | AR5: 0 | AS5: 1 | AT5: 其他 | AU5: 0 | AV5: 0 | AW5: 其他 | AX5: 0 | AY5: 0 | AZ5: 其他 | BA5: 0 | BB5: 0 | BC5: 0 | BD5: 0 | BE5: 0 | BF5: 0 | BG5: 0 | BH5: 3 | BI5: =SUM(BB5:BH5) -> 3 | BJ5: 是 | BK5: 主城区 | BL5: MALL店
A6: 海南省 | B6: 东方市 | C6: 东方市 | D6: 东河镇 | E6: 已存在 | F6: CNSCN340904 | G6: 东方东河东信翼电信专营店 | H6: 55014110 | I6: CNSQCN00054159 | J6: 综合卖场 | K6: =SUM(T6:AI6) -> 59 | M6: 营业中 | N6: 排它-电信 | O6: 王和立 | P6: 18976120333 | Q6: 东方市东河镇东风路十字路口 | R6: 100073133701 | S6: 东方东河东信翼电信专营店 | T6: 28 | U6: 2 | V6: 0 | W6: 5 | X6: 0 | Y6: 3 | Z6: 6 | AA6: 0 | AB6: 15 | AC6: 0 | AD6: 0 | AE6: 0 | AF6: 0 | AG6: 0 | AH6: 0 | AI6: 0 | AJ6: 0 | AK6: 其他 | AL6: 0 | AM6: 0 | AN6: 其他 | AO6: 0 | AP6: 0 | AQ6: 其他 | AR6: 0 | AS6: 1 | AT6: TOP1 | AU6: 0 | AV6: 0 | AW6: 其他 | AX6: 0 | AY6: 1 | AZ6: TOP2 | BA6: 0 | BB6: 0 | BC6: 0 | BD6: 0 | BE6: 0 | BF6: 0 | BG6: 0 | BH6: 2 | BI6: 2 | BJ6: 是 | BK6: 非主城区 | BL6: 街边店
A7: 海南省 | B7: 东方市 | C7: 东方市 | D7: 八所镇 | E7: 已存在 | F7: CNSCN345130 | G7: 东方八所琼西路巨为移动专营店 | H7: 55014109 | I7: CNSQCN00054154 | J7: 综合卖场 | K7: =SUM(T7:AI7) -> 400 | M7: 营业中 | N7: 排它-移动 | O7: 符重鹏 | P7: 15109896206 | Q7: 海南省东方市八所镇琼西路琼西医院对面 | R7: 200018297501 | S7: 东方八所巨为手机连锁店 | T7: 200 | U7: 0 | V7: 0 | W7: 50 | X7: 0 | Y7: 10 | Z7: 100 | AA7: 0 | AB7: 40 | AC7: 0 | AD7: 0 | AE7: 0 | AF7: 0 | AG7: 0 | AH7: 0 | AI7: 0 | AJ7: 1 | AK7: TOP1 | AL7: 0 | AM7: 0 | AN7: 其他 | AO7: 0 | AP7: 0 | AQ7: 其他 | AR7: 0 | AS7: 1 | AT7: TOP1 | AU7: 0 | AV7: 0 | AW7: 其他 | AX7: 0 | AY7: 0 | AZ7: 其他 | BA7: 0 | BB7: 0 | BC7: 0 | BD7: 0 | BE7: 0 | BF7: 0 | BG7: 0 | BH7: 2 | BI7: 2 | BJ7: 是 | BK7: 主城区 | BL7: 街边店
A8: 海南省 | B8: 东方市 | C8: 东方市 | D8: 八所镇 | E8: 已存在 | F8: CNSCN072112 | G8: 电信连锁-东方城东主营业厅(金鹏) | H8: 55014109 | I8: CNSQCN00054154 | J8: 运营商厅店 | K8: =SUM(T8:AI8) -> 248 | M8: 营业中 | N8: 排它-电信 | O8: 孙学彬 | P8: 18976332378 | Q8: 海南省东方市八所镇东方大道41号中国电信大楼一楼 | R8: 100029648601 | S8: 海南金鹏东宜通信工程有限公司 | T8: 60 | U8: 76 | V8: 5 | W8: 53 | X8: 35 | Y8: 0 | Z8: 12 | AA8: 0 | AB8: 7 | AC8: 0 | AD8: 0 | AE8: 0 | AF8: 0 | AG8: 0 | AH8: 0 | AI8: 0 | AJ8: 1 | AK8: 其他 | AL8: 0 | AM8: 1 | AN8: 其他 | AO8: 0 | AP8: 1 | AQ8: 其他 | AR8: 0 | AS8: 1 | AT8: 其他 | AU8: 1 | AV8: 1 | AW8: 其他 | AX8: 0 | AY8: 1 | AZ8: 其他 | BA8: 0 | BB8: 0 | BC8: 0 | BD8: 0 | BE8: 0 | BF8: 0 | BG8: 1 | BH8: 6 | BI8: 7 | BJ8: 是 | BK8: 主城区 | BL8: 街边店
A9: 海南省 | B9: 东方市 | C9: 东方市 | D9: 八所镇 | E9: 已存在 | F9: CNSCN132726 | G9: 东方八所快捷解放西路电信营业厅 | H9: 55014109 | I9: CNSQCN00054157 | J9: 运营商厅店 | K9: =SUM(T9:AI9) -> 104 | M9: 营业中 | N9: 排它-电信 | O9: 张业慧 | P9: 18976543282 | Q9: 海南省东方市八所镇解放西路4G数码城vivo 门头处 | R9: 100060492301 | S9: 东方八所快捷通信店 | T9: 34 | U9: 17 | V9: 1 | W9: 5 | X9: 0 | Y9: 0 | Z9: 25 | AA9: 2 | AB9: 20 | AC9: 0 | AD9: 0 | AE9: 0 | AF9: 0 | AG9: 0 | AH9: 0 | AI9: 0 | AJ9: 1 | AK9: 其他 | AL9: 0 | AM9: 1 | AN9: 其他 | AO9: 0 | AP9: 1 | AQ9: 其他 | AR9: 0 | AS9: 0 | AT9: 其他 | AU9: 0 | AV9: 0 | AW9: 其他 | AX9: 0 | AY9: 0 | AZ9: 其他 | BA9: 0 | BB9: 0 | BC9: 0 | BD9: 0 | BE9: 1 | BF9: 0 | BG9: 0 | BH9: 3 | BI9: 4 | BJ9: 是 | BK9: 主城区 | BL9: 街边店
A10: 海南省 | B10: 东方市 | C10: 东方市 | D10: 八所镇 | F10: SCN279515 | G10: 东方兴达东海路体验店 | H10: 55014109 | I10: CNSQCN00054839 | K10: =SUM(T10:AI10) -> 0 | M10: 闭店 | O10: 周志攀 | P10: 13519850230 | Q10: 海南省东方市八所镇东海路57号 | R10: 100032170201 | S10: 东方八所兴达数码城
A11: 海南省 | B11: 东方市 | C11: 东方市 | D11: 八所镇 | E11: 已存在 | F11: CNSCN352631 | G11: 东方解放路老客联通合作厅 | H11: 55014109 | I11: CNSQCN00054157 | J11: 综合卖场 | K11: =SUM(T11:AI11) -> 112 | M11: 营业中 | N11: 排它-联通 | O11: 符进花 | P11: 13907599501 | Q11: 海南省东方市八所镇解放西路59号新华书店一楼 | R11: 200020610801 | S11: 东方八所老客数码产品店 | T11: 35 | U11: 24 | V11: 0 | W11: 16 | X11: 9 | Y11: 15 | Z11: 11 | AA11: 2 | AB11: 0 | AC11: 0 | AD11: 0 | AE11: 0 | AF11: 0 | AG11: 0 | AH11: 0 | AI11: 0 | AJ11: 1 | AK11: TOP1 | AL11: 0 | AM11: 0 | AN11: 其他 | AO11: 0 | AP11: 0 | AQ11: 其他 | AR11: 0 | AS11: 1 | AT11: 其他 | AU11: 0 | AV11: 0 | AW11: 其他 | AX11: 0 | AY11: 1 | AZ11: TOP2 | BA11: 0 | BB11: 0 | BC11: 0 | BD11: 0 | BE11: 0 | BF11: 0 | BG11: 0 | BH11: 3 | BI11: 3 | BJ11: 是 | BK11: 主城区 | BL11: 街边店
A12: 海南省 | B12: 东方市 | C12: 东方市 | D12: 八所镇 | E12: 已存在 | F12: CNSCN302635 | G12: 东方八所东海路恒晟通电信专营店 | H12: 55014109 | I12: CNSQCN00054839 | J12: 综合卖场 | K12: =SUM(T12:AI12) -> 104 | M12: 营业中 | N12: 排它-电信 | O12: 杨云灵 | P12: 18089711133 | Q12: 海南省东方市八所镇东海路62号艺豪宾馆首层 | R12: 100084347601 | S12: 儋州恒雁通信有限公司 | T12: 51 | U12: 4 | V12: 0 | W12: 5 | X12: 0 | Y12: 10 | Z12: 12 | AA12: 0 | AB12: 22 | AC12: 0 | AD12: 0 | AE12: 0 | AF12: 0 | AG12: 0 | AH12: 0 | AI12: 0 | AJ12: 1 | AK12: 其他 | AL12: 0 | AM12: 1 | AN12: 其他 | AO12: 0 | AP12: 0 | AQ12: 其他 | AR12: 0 | AS12: 0 | AT12: 其他 | AU12: 0 | AV12: 0 | AW12: 其他 | AX12: 0 | AY12: 0 | AZ12: 其他 | BA12: 0 | BB12: 0 | BC12: 0 | BD12: 0 | BE12: 0 | BF12: 0 | BG12: 0 | BH12: 4 | BI12: 4 | BJ12: 是 | BK12: 主城区 | BL12: 街边店
A13: 海南省 | B13: 东方市 | C13: 东方市 | D13: 八所镇 | E13: 已存在 | F13: CNSCN299925 | G13: 东方东海喜爱数码移动手机专卖店 | H13: 55014109 | I13: CNSQCN00054157 | J13: 综合卖场 | K13: =SUM(T13:AI13) -> 75 | M13: 营业中 | N13: 排它-移动 | O13: 柳家豪 | P13: 18889692927 | Q13: 海南省东方市八所镇永安西路36号第三间 | R13: 100063737601 | S13: 东方东海喜爱数码手机专卖店 | T13: 35 | U13: 3 | V13: 0 | W13: 8 | X13: 0 | Y13: 2 | Z13: 12 | AA13: 0 | AB13: 15 | AC13: 0 | AD13: 0 | AE13: 0 | AF13: 0 | AG13: 0 | AH13: 0 | AI13: 0 | AJ13: 0 | AK13: 其他 | AL13: 0 | AM13: 1 | AN13: 其他 | AO13: 0 | AP13: 1 | AQ13: 其他 | AR13: 0 | AS13: 0 | AT13: 其他 | AU13: 0 | AV13: 0 | AW13: 其他 | AX13: 0 | AY13: 0 | AZ13: 其他 | BA13: 0 | BB13: 0 | BC13: 0 | BD13: 0 | BE13: 0 | BF13: 0 | BG13: 0 | BH13: 1 | BI13: 1 | BJ13: 是 | BK13: 主城区 | BL13: 街边店
A14: 海南省 | B14: 东方市 | C14: 东方市 | D14: 八所镇 | E14: 已存在 | F14: CNSCN299924 | G14: 东方鱼鳞洲营业厅 | H14: 55014109 | I14: CNSQCN00054157 | J14: 运营商厅店 | K14: =SUM(T14:AI14) -> 47 | M14: 营业中 | N14: 排它-联通 | O14: 倪小婷 | P14: 186089978260 | Q14: 海南省东方市八所镇解放西路73号 | R14: 100015014301 | S14: 联通华盛通信有限公司海南分公司 | T14: 23 | U14: 1 | V14: 0 | W14: 4 | X14: 0 | Y14: 1 | Z14: 8 | AA14: 0 | AB14: 10 | AC14: 0 | AD14: 0 | AE14: 0 | AF14: 0 | AG14: 0 | AH14: 0 | AI14: 0 | AJ14: 0 | AK14: 其他 | AL14: 0 | AM14: 0 | AN14: 其他 | AO14: 0 | AP14: 0 | AQ14: 其他 | AR14: 0 | AS14: 0 | AT14: 其他 | AU14: 0 | AV14: 0 | AW14: 其他 | AX14: 0 | AY14: 0 | AZ14: 其他 | BA14: 0 | BB14: 0 | BC14: 0 | BD14: 0 | BE14: 0 | BF14: 0 | BG14: 0 | BH14: 4 | BI14: 4 | BJ14: 是 | BK14: 主城区 | BL14: 街边店
A15: 海南省 | B15: 东方市 | C15: 东方市 | D15: 东河镇 | E15: 已存在 | F15: CNSCN299922 | G15: 东方东河颖武联通电讯专营店 | H15: 55014110 | I15: CNSQCN00054159 | J15: 综合卖场 | K15: =SUM(T15:AI15) -> 87 | M15: 营业中 | N15: 排它-联通 | O15: 钟萍 | P15: 18976692222 | Q15: 海南省东方市东河镇市场斜对面中国联通手机店 | R15: 100080560401 | S15: 东方东河颖武电讯专营店 | T15: 39 | U15: 5 | V15: 0 | W15: 13 | X15: 0 | Y15: 5 | Z15: 10 | AA15: 0 | AB15: 15 | AC15: 0 | AD15: 0 | AE15: 0 | AF15: 0 | AG15: 0 | AH15: 0 | AI15: 0 | AJ15: 1 | AK15: 其他 | AL15: 0 | AM15: 1 | AN15: 其他 | AO15: 0 | AP15: 1 | AQ15: 其他 | AR15: 0 | AS15: 0 | AT15: 其他 | AU15: 0 | AV15: 0 | AW15: 其他 | AX15: 0 | AY15: 0 | AZ15: 其他 | BA15: 0 | BB15: 0 | BC15: 0 | BD15: 0 | BE15: 0 | BF15: 0 | BG15: 0 | BH15: 1 | BI15: 1 | BJ15: 是 | BK15: 非主城区 | BL15: 街边店
A16: 海南省 | B16: 东方市 | C16: 东方市 | D16: 八所镇 | E16: 已存在 | F16: CNSCN299921 | G16: 电信连锁-东方解放路营业厅(翼讯达) | H16: 55014109 | I16: CNSQCN00054157 | J16: 运营商厅店 | K16: =SUM(T16:AI16) -> 215 | M16: 营业中 | N16: 排它-电信 | O16: 王远柳 | P16: 18907628586 | Q16: 海南省东方市八所镇解放西路电信营业厅54-1号 | R16: 100013317301 | S16: 海口翼讯达通讯器材有限公司 | T16: 88 | U16: 20 | V16: 0 | W16: 40 | X16: 0 | Y16: 5 | Z16: 32 | AA16: 5 | AB16: 25 | AC16: 0 | AD16: 0 | AE16: 0 | AF16: 0 | AG16: 0 | AH16: 0 | AI16: 0 | AJ16: 1 | AK16: 其他 | AL16: 0 | AM16: 1 | AN16: 其他 | AO16: 0 | AP16: 1 | AQ16: 其他 | AR16: 0 | AS16: 1 | AT16: 其他 | AU16: 0 | AV16: 0 | AW16: 其他 | AX16: 0 | AY16: 0 | AZ16: 其他 | BA16: 0 | BB16: 0 | BC16: 0 | BD16: 0 | BE16: 0 | BF16: 0 | BG16: 0 | BH16: 6 | BI16: 6 | BJ16: 是 | BK16: 主城区 | BL16: 街边店
A17: 海南省 | B17: 东方市 | C17: 东方市 | D17: 八所镇 | E17: 已存在 | F17: CNSCN284844 | G17: 东方市东海九龙通讯手机店 | H17: 55014109 | I17: CNSQCN00054158 | J17: 综合卖场 | K17: =SUM(T17:AI17) -> 101 | M17: 营业中 | N17: 排它-移动 | O17: 黎灿辉 | P17: 15008008111 | Q17: 海南省东方市八所镇东方大道2-3号 | R17: 100046478701 | S17: 东方市东海九龙通讯手机店 | T17: 33 | U17: 15 | V17: 3 | W17: 12 | X17: 0 | Y17: 7 | Z17: 6 | AA17: 4 | AB17: 21 | AC17: 0 | AD17: 0 | AE17: 0 | AF17: 0 | AG17: 0 | AH17: 0 | AI17: 0 | AJ17: 1 | AK17: TOP1 | AL17: 0 | AM17: 0 | AN17: 其他 | AO17: 0 | AP17: 1 | AQ17: 其他 | AR17: 0 | AS17: 0 | AT17: 其他 | AU17: 0 | AV17: 0 | AW17: 其他 | AX17: 0 | AY17: 0 | AZ17: 其他 | BA17: 0 | BB17: 0 | BC17: 0 | BD17: 0 | BE17: 0 | BF17: 0 | BG17: 0 | BH17: 5 | BI17: 5 | BJ17: 是 | BK17: 主城区 | BL17: 街边店
A18: 海南省 | B18: 东方市 | C18: 东方市 | D18: 感城镇 | E18: 已存在 | F18: CNSCN284843 | G18: 东方感城星源移动专营 | H18: 55014112 | I18: CNSQCN00054160 | J18: 综合卖场 | K18: =SUM(T18:AI18) -> 109 | M18: 营业中 | N18: 排它-移动 | O18: 邱芳东 | P18: 13876440168 | Q18: 海南省东方市感城镇感城村感恩大道2号 | R18: 200003081301 | S18: 东方感城星源手机店 | T18: 45 | U18: 10 | V18: 0 | W18: 10 | X18: 0 | Y18: 4 | Z18: 20 | AA18: 0 | AB18: 20 | AC18: 0 | AD18: 0 | AE18: 0 | AF18: 0 | AG18: 0 | AH18: 0 | AI18: 0 | AJ18: 1 | AK18: 其他 | AL18: 0 | AM18: 1 | AN18: 其他 | AO18: 0 | AP18: 1 | AQ18: 其他 | AR18: 0 | AS18: 0 | AT18: 其他 | AU18: 0 | AV18: 0 | AW18: 其他 | AX18: 0 | AY18: 0 | AZ18: 其他 | BA18: 0 | BB18: 0 | BC18: 0 | BD18: 0 | BE18: 0 | BF18: 0 | BG18: 0 | BH18: 2 | BI18: 2 | BJ18: 是 | BK18: 非主城区 | BL18: 街边店
A19: 海南省 | B19: 东方市 | C19: 东方市 | D19: 八所镇 | E19: 已存在 | F19: RYCM08980130 | G19: 东方八所强国强东海路移动移动营业厅 | H19: 55014109 | I19: CNSQCN00054839 | J19: 综合卖场 | K19: =SUM(T19:AI19) -> 0 | M19: 营业中 | N19: 排它-移动 | O19: 谢飞 | P19: 18889498555 | Q19: 海南省东方市东海路地道站商品一楼456号铺面 | R19: 100036112401 | S19: 东方八所大有通讯店
A20: 海南省 | B20: 东方市 | C20: 东方市 | D20: 八所镇 | E20: 已存在 | F20: RYCT08980062 | G20: 东方八所兴达解放西路数码城 | H20: 55014109 | I20: CNSQCN00054839 | J20: 综合卖场 | K20: =SUM(T20:AI20) -> 209 | M20: 营业中 | N20: 排它-移动 | O20: 苏塔 | P20: 13198958799 | Q20: 海南省东方市八所镇解放西路兴达数码城 | R20: 100032170201 | S20: 东方八所兴达数码城 | T20: 54 | U20: 40 | V20: 4 | W20: 15 | X20: 10 | Y20: 0 | Z20: 32 | AA20: 5 | AB20: 40 | AC20: 0 | AD20: 1 | AE20: 1 | AF20: 2 | AG20: 1 | AH20: 3 | AI20: 1 | AJ20: 1 | AK20: 其他 | AL20: 0 | AM20: 1 | AN20: TOP2 | AO20: 0 | AP20: 1 | AQ20: 其他 | AR20: 0 | AS20: 1 | AT20: 其他 | AU20: 0 | AV20: 0 | AW20: 其他 | AX20: 0 | AY20: 0 | AZ20: 其他 | BA20: 0 | BB20: 0 | BC20: 1 | BD20: 0 | BE20: 1 | BF20: 0 | BG20: 1 | BH20: 5 | BI20: 8 | BJ20: 是 | BK20: 主城区 | BL20: 街边店
A21: 海南省 | B21: 东方市 | C21: 东方市 | D21: 板桥镇 | E21: 已存在 | F21: CNSCN317706 | G21: 东方市板桥腾珑手机专营店 | H21: 55014113 | I21: CNSQCN00054155 | J21: 综合卖场 | K21: =SUM(T21:AI21) -> 95 | M21: 营业中 | N21: 排它-移动 | O21: 王隆健 | P21: 18976125399 | Q21: 海南省东方市板桥镇复兴北路107号 | R21: 100061969301 | S21: 东方感城腾龙手机专卖店 | T21: 40 | U21: 8 | V21: 0 | W21: 5 | X21: 5 | Y21: 5 | Z21: 12 | AA21: 0 | AB21: 20 | AC21: 0 | AD21: 0 | AE21: 0 | AF21: 0 | AG21: 0 | AH21: 0 | AI21: 0 | AJ21: 1 | AK21: 其他 | AL21: 0 | AM21: 1 | AN21: TOP3 | AO21: 0 | AP21: 1 | AQ21: 其他 | AR21: 0 | AS21: 0 | AT21: 其他 | AU21: 0 | AV21: 0 | AW21: 其他 | AX21: 0 | AY21: 0 | AZ21: 其他 | BA21: 0 | BB21: 0 | BC21: 0 | BD21: 0 | BE21: 0 | BF21: 0 | BG21: 0 | BH21: 3 | BI21: 3 | BJ21: 是 | BK21: 非主城区 | BL21: 街边店
A22: 海南省 | B22: 东方市 | C22: 东方市 | D22: 感城镇 | E22: 无规划 | F22: CNSCN110792 | G22: 东方市感城永成移动通信 | H22: 55014112 | I22: CNSQCN00054160 | J22: 综合卖场 | K22: =SUM(T22:AI22) -> 91 | M22: 营业中 | N22: 排它-移动 | O22: 杨勇 | P22: 13687568008 | Q22: 海南省东方市感城镇河堤路 | R22: 100080561801 | S22: 东方感城永成手机通讯店 | T22: 31 | U22: 15 | V22: 0 | W22: 10 | X22: 8 | Y22: 5 | Z22: 5 | AA22: 0 | AB22: 17 | AC22: 0 | AD22: 0 | AE22: 0 | AF22: 0 | AG22: 0 | AH22: 0 | AI22: 0 | AJ22: 1 | AK22: 其他 | AL22: 0 | AM22: 0 | AN22: TOP1 | AO22: 0 | AP22: 1 | AQ22: 其他 | AR22: 0 | AS22: 1 | AT22: TOP1 | AU22: 0 | AV22: 0 | AW22: 其他 | AX22: 0 | AY22: 0 | AZ22: 其他 | BA22: 0 | BB22: 0 | BC22: 0 | BD22: 0 | BE22: 0 | BF22: 0 | BG22: 0 | BH22: 3 | BI22: 3 | BJ22: 是 | BK22: 非主城区 | BL22: 街边店
A23: 海南省 | B23: 东方市 | C23: 东方市 | D23: 感城镇 | E23: 已存在 | F23: CNSCN110791 | G23: 东方感城卫飞手机专营店 | H23: 55014112 | I23: CNSQCN00054160 | J23: 综合卖场 | K23: =SUM(T23:AI23) -> 151 | M23: 营业中 | N23: 排它-移动 | O23: 苏定卫 | P23: 13976878008 | Q23: 东方市感城镇河堤路5号 | R23: 100046483001 | S23: 东方感城定卫手机店 | T23: 52 | U23: 20 | V23: 3 | W23: 7 | X23: 0 | Y23: 10 | Z23: 24 | AA23: 0 | AB23: 35 | AC23: 0 | AD23: 0 | AE23: 0 | AF23: 0 | AG23: 0 | AH23: 0 | AI23: 0 | AJ23: 1 | AK23: 其他 | AL23: 0 | AM23: 1 | AN23: TOP2 | AO23: 0 | AP23: 1 | AQ23: 其他 | AR23: 0 | AS23: 1 | AT23: 其他 | AU23: 0 | AV23: 0 | AW23: 其他 | AX23: 0 | AY23: 0 | AZ23: 其他 | BA23: 0 | BB23: 0 | BC23: 0 | BD23: 0 | BE23: 1 | BF23: 0 | BG23: 1 | BH23: 4 | BI23: 6 | BJ23: 是 | BK23: 非主城区 | BL23: 街边店
A24: 海南省 | B24: 东方市 | C24: 东方市 | D24: 八所镇 | E24: 已存在 | F24: CNSCN110785 | G24: 东方东海惠中手机店 | H24: 55014109 | I24: CNSQCN00054839 | J24: 综合卖场 | K24: =SUM(T24:AI24) -> 143 | M24: 营业中 | N24: 排它-移动 | O24: 苏塔 | P24: 13198958799 | Q24: 东方市金岛大厦一楼9号铺面 | R24: 100032170201 | S24: 东方八所兴达数码城 | T24: 50 | U24: 18 | V24: 3 | W24: 10 | X24: 7 | Y24: 16 | Z24: 10 | AA24: 2 | AB24: 27 | AC24: 0 | AD24: 0 | AE24: 0 | AF24: 0 | AG24: 0 | AH24: 0 | AI24: 0 | AJ24: 1 | AK24: 其他 | AL24: 0 | AM24: 0 | AN24: 其他 | AO24: 0 | AP24: 1 | AQ24: 其他 | AR24: 0 | AS24: 1 | AT24: 其他 | AU24: 0 | AV24: 0 | AW24: 其他 | AX24: 0 | AY24: 0 | AZ24: 其他 | BA24: 0 | BB24: 0 | BC24: 0 | BD24: 0 | BE24: 0 | BF24: 0 | BG24: 0 | BH24: 3 | BI24: 3 | BJ24: 是 | BK24: 主城区 | BL24: 街边店
A25: 海南省 | B25: 东方市 | C25: 东方市 | D25: 感城镇 | E25: 已存在 | F25: CNSCN131205 | G25: 东方感城玉心移动营业厅 | H25: 55014112 | I25: CNSQCN00054160 | J25: 综合卖场 | K25: =SUM(T25:AI25) -> 145 | M25: 营业中 | N25: 排它-移动 | O25: 苏杰雄 | P25: 13976136788 | Q25: 海南省东方市感城镇河堤路右侧95号 | R25: 100073941801 | S25: 东方感城玉心手机店 | T25: 59 | U25: 14 | V25: 0 | W25: 18 | X25: 0 | Y25: 7 | Z25: 17 | AA25: 0 | AB25: 30 | AC25: 0 | AD25: 0 | AE25: 0 | AF25: 0 | AG25: 0 | AH25: 0 | AI25: 0 | AJ25: 1 | AK25: TOP3 | AL25: 0 | AM25: 1 | AN25: TOP1 | AO25: 0 | AP25: 1 | AQ25: 其他 | AR25: 0 | AS25: 1 | AT25: TOP1 | AU25: 0 | AV25: 0 | AW25: 其他 | AX25: 0 | AY25: 0 | AZ25: 其他 | BA25: 0 | BB25: 0 | BC25: 0 | BD25: 0 | BE25: 0 | BF25: 0 | BG25: 0 | BH25: 2 | BI25: 2 | BJ25: 是 | BK25: 非主城区 | BL25: 街边店
A26: 海南省 | B26: 东方市 | C26: 东方市 | D26: 感城镇 | E26: 已存在 | F26: RYCU08980019 | G26: 东方感城感恩大道星豪联通营业厅 | H26: 55014112 | I26: CNSQCN00054160 | J26: 综合卖场 | K26: =SUM(T26:AI26) -> 155 | M26: 营业中 | N26: 排它-电信 | O26: 林宝 | P26: 18689951685 | Q26: 海南省东方市感城镇感恩大道17号 | R26: 100049753101 | S26: 东方感城星豪手机广场 | T26: 48 | U26: 27 | V26: 3 | W26: 25 | X26: 0 | Y26: 2 | Z26: 22 | AA26: 0 | AB26: 28 | AC26: 0 | AD26: 0 | AE26: 0 | AF26: 0 | AG26: 0 | AH26: 0 | AI26: 0 | AJ26: 1 | AK26: TOP3 | AL26: 0 | AM26: 1 | AN26: 其他 | AO26: 0 | AP26: 1 | AQ26: 其他 | AR26: 0 | AS26: 0 | AT26: 其他 | AU26: 0 | AV26: 0 | AW26: 其他 | AX26: 0 | AY26: 0 | AZ26: 其他 | BA26: 0 | BB26: 0 | BC26: 0 | BD26: 0 | BE26: 1 | BF26: 0 | BG26: 0 | BH26: 3 | BI26: 4 | BJ26: 是 | BK26: 非主城区 | BL26: 街边店
A27: 海南省 | B27: 东方市 | C27: 东方市 | D27: 新龙镇 | E27: 已存在 | F27: CNSCN284742 | G27: 东方新龙镇灵霄移动专营店 | H27: 55014116 | I27: CNSQCN00054161 | J27: 综合卖场 | K27: =SUM(T27:AI27) -> 109 | M27: 营业中 | N27: 排它-移动 | O27: 符邦敏 | P27: 15008977420 | Q27: 海南省东方市新龙镇龙佑村33号 | R27: 200003605001 | S27: 东方新龙镇灵霄手机专营店 | T27: 37 | U27: 13 | V27: 2 | W27: 15 | X27: 2 | Y27: 2 | Z27: 17 | AA27: 1 | AB27: 15 | AC27: 0 | AD27: 0 | AE27: 1 | AF27: 1 | AG27: 1 | AH27: 1 | AI27: 1 | AJ27: 1 | AK27: TOP1 | AL27: 0 | AM27: 0 | AN27: 其他 | AO27: 0 | AP27: 0 | AQ27: 其他 | AR27: 0 | AS27: 0 | AT27: 其他 | AU27: 0 | AV27: 0 | AW27: 其他 | AX27: 0 | AY27: 0 | AZ27: 其他 | BA27: 0 | BB27: 0 | BC27: 0 | BD27: 0 | BE27: 0 | BF27: 0 | BG27: 0 | BH27: 2 | BI27: 2 | BJ27: 是 | BK27: 非主城区 | BL27: 街边店
A28: 海南省 | B28: 东方市 | C28: 东方市 | D28: 八所镇 | E28: 已存在 | F28: CNSCN284741 | G28: 东方八所解放路南海移动营业厅 | H28: 55014109 | I28: CNSQCN00054157 | J28: 综合卖场 | K28: =SUM(T28:AI28) -> 75 | M28: 装修中 | N28: 排它-移动 | O28: 陈春蕊 | P28: 13876000364 | Q28: 海南省东方市八所镇解放西路南海宾馆1楼 | R28: 200018267701 | S28: 海南高乐电讯设备有限公司 | T28: 32 | U28: 6 | V28: 0 | W28: 8 | X28: 0 | Y28: 3 | Z28: 11 | AA28: 0 | AB28: 15 | AC28: 0 | AD28: 0 | AE28: 0 | AF28: 0 | AG28: 0 | AH28: 0 | AI28: 0 | AJ28: 1 | AK28: TOP2 | AL28: 0 | AM28: 1 | AN28: 其他 | AO28: 0 | AP28: 1 | AQ28: 其他 | AR28: 0 | AS28: 1 | AT28: 其他 | AU28: 0 | AV28: 0 | AW28: 其他 | AX28: 0 | AY28: 0 | AZ28: 其他 | BA28: 0 | BB28: 0 | BC28: 0 | BD28: 0 | BE28: 0 | BF28: 0 | BG28: 1 | BH28: 5 | BI28: 6 | BJ28: 是 | BK28: 主城区 | BL28: 街边店
A29: 海南省 | B29: 东方市 | C29: 东方市 | D29: 八所镇 | E29: 已存在 | F29: CNSCN301738 | G29: 东方八所华人国际移动营业厅 | H29: 55014109 | I29: CNSQCN00054157 | J29: 运营商厅店 | K29: =SUM(T29:AI29) -> 89 | M29: 营业中 | N29: 排它-移动 | O29: 陈春蕊 | P29: 13876000364 | Q29: 东方市八所镇解放中路华人国际电影城一楼商铺 | R29: 200018267701 | S29: 海南高乐电讯设备有限公司 | T29: 38 | U29: 7 | V29: 0 | W29: 8 | X29: 0 | Y29: 4 | Z29: 11 | AA29: 3 | AB29: 18 | AC29: 0 | AD29: 0 | AE29: 0 | AF29: 0 | AG29: 0 | AH29: 0 | AI29: 0 | AJ29: 1 | AK29: 其他 | AL29: 0 | AM29: 1 | AN29: 其他 | AO29: 0 | AP29: 1 | AQ29: 其他 | AR29: 0 | AS29: 0 | AT29: 其他 | AU29: 0 | AV29: 0 | AW29: 其他 | AX29: 0 | AY29: 0 | AZ29: 其他 | BA29: 0 | BB29: 0 | BC29: 0 | BD29: 0 | BE29: 1 | BF29: 0 | BG29: 0 | BH29: 2 | BI29: 3 | BJ29: 是 | BK29: 主城区 | BL29: 街边店
A30: 海南省 | B30: 东方市 | C30: 东方市 | D30: 八所镇 | E30: 已存在 | F30: RYRA08980220 | G30: 东方八所海升东海路手机店 | H30: 55014109 | I30: CNSQCN00054839 | J30: 综合卖场 | K30: =SUM(T30:AI30) -> 154 | M30: 营业中 | N30: 排它-移动 | O30: 高美美 | P30: 18889200520 | Q30: 东方市东海路云天酒店旁 | R30: 100051972901 | S30: 东方东海乐信手机店 | T30: 46 | U30: 30 | V30: 1 | W30: 7 | X30: 0 | Y30: 10 | Z30: 32 | AA30: 3 | AB30: 25 | AC30: 0 | AD30: 0 | AE30: 0 | AF30: 0 | AG30: 0 | AH30: 0 | AI30: 0 | AJ30: 1 | AK30: TOP2 | AL30: 0 | AM30: 1 | AN30: TOP3 | AO30: 0 | AP30: 1 | AQ30: 其他 | AR30: 0 | AS30: 1 | AT30: 其他 | AU30: 1 | AV30: 0 | AW30: 其他 | AX30: 0 | AY30: 0 | AZ30: 其他 | BA30: 0 | BB30: 0 | BC30: 0 | BD30: 0 | BE30: 1 | BF30: 0 | BG30: 1 | BH30: 3 | BI30: 5 | BJ30: 是 | BK30: 主城区 | BL30: 街边店
A31: 海南省 | B31: 东方市 | C31: 东方市 | D31: 八所镇 | E31: 已存在 | F31: CNSCN222546 | G31: 东方东海大有领界电信店 | H31: 55014109 | I31: CNSQCN00054839 | J31: 综合卖场 | K31: =SUM(T31:AI31) -> 125 | M31: 营业中 | N31: 排它-电信 | O31: 李燕琼 | P31: 18976129991 | Q31: 海南省东方市八所镇东海路57号东海加油站旁1楼 | R31: 100036112401 | S31: 东方八所大有通讯店 | T31: 44 | U31: 17 | V31: 2 | W31: 8 | X31: 0 | Y31: 9 | Z31: 25 | AA31: 0 | AB31: 20 | AC31: 0 | AD31: 0 | AE31: 0 | AF31: 0 | AG31: 0 | AH31: 0 | AI31: 0 | AJ31: 1 | AK31: TOP3 | AL31: 0 | AM31: 1 | AN31: TOP3 | AO31: 0 | AP31: 1 | AQ31: 其他 | AR31: 0 | AS31: 1 | AT31: 其他 | AU31: 1 | AV31: 0 | AW31: 其他 | AX31: 0 | AY31: 0 | AZ31: 其他 | BA31: 0 | BB31: 0 | BC31: 0 | BD31: 0 | BE31: 1 | BF31: 0 | BG31: 0 | BH31: 3 | BI31: 4 | BJ31: 是 | BK31: 主城区 | BL31: 街边店
A32: 海南省 | B32: 东方市 | C32: 东方市 | D32: 八所镇 | F32: SCN272996 | G32: 东方华商万达广场店-老店帐号 | H32: 55014109 | I32: CNSQCN00054154 | K32: =SUM(T32:AI32) -> 0 | M32: 闭店 | O32: 林昌睿 | P32: 18876836788 | Q32: 海南东⽅市八所镇解放东路与感恩南路交汇处万达⼴场1楼1031 | R32: 100013317601 | S32: 海南鸿运四海电子科技有限公司
A33: 海南省 | B33: 东方市 | C33: 东方市 | D33: 八所镇 | F33: CNSCN300143 | G33: 东方市东海路联通营业厅 | H33: 55014109 | I33: CNSQCN00054158 | K33: =SUM(T33:AI33) -> 0 | M33: 闭店 | O33: 杨江浪 | P33: 18608959300 | Q33: 海南省东方市东海路联通营业厅（树宝宾馆旁） | R33: 100015014301 | S33: 联通华盛通信有限公司海南分公司
A34: 海南省 | B34: 东方市 | C34: 东方市 | D34: 四更镇 | E34: 已存在 | F34: CNSCN128707 | G34: 东方四更金菊全网通手机卖场 | H34: 55014115 | I34: CNSQCN00054163 | J34: 综合卖场 | K34: =SUM(T34:AI34) -> 68 | M34: 营业中 | N34: 排它-电信 | O34: 符金菊 | P34: 18117720757 | Q34: 海南省东方市四更镇镇政府北商品房 | R34: 100079112301 | S34: 东方市四更电信代理服务点 | T34: 34 | U34: 1 | V34: 0 | W34: 5 | X34: 0 | Y34: 5 | Z34: 8 | AA34: 0 | AB34: 15 | AC34: 0 | AD34: 0 | AE34: 0 | AF34: 0 | AG34: 0 | AH34: 0 | AI34: 0 | AJ34: 1 | AK34: 其他 | AL34: 0 | AM34: 1 | AN34: 其他 | AO34: 0 | AP34: 1 | AQ34: 其他 | AR34: 0 | AS34: 0 | AT34: 其他 | AU34: 0 | AV34: 0 | AW34: 其他 | AX34: 0 | AY34: 0 | AZ34: 其他 | BA34: 0 | BB34: 0 | BC34: 0 | BD34: 0 | BE34: 0 | BF34: 0 | BG34: 0 | BH34: 1 | BI34: 1 | BJ34: 是 | BK34: 非主城区 | BL34: 街边店
A35: 海南省 | B35: 东方市 | C35: 东方市 | D35: 大田镇 | E35: 已存在 | F35: CNSCN128704 | G35: 东方大田杰兰手机卖场 | H35: 55014111 | I35: CNSQCN00054156 | J35: 综合卖场 | K35: =SUM(T35:AI35) -> 75 | M35: 营业中 | N35: 排它-电信 | O35: 李杰兰 | P35: 13307543003 | Q35: 海南省东方市大田镇零公里猕猴岭林场一巷11号 | R35: 100073941901 | S35: 东方大田杰兰手机卖场 | T35: 36 | U35: 2 | V35: 0 | W35: 5 | X35: 0 | Y35: 7 | Z35: 12 | AA35: 0 | AB35: 13 | AC35: 0 | AD35: 0 | AE35: 0 | AF35: 0 | AG35: 0 | AH35: 0 | AI35: 0 | AJ35: 1 | AK35: 其他 | AL35: 0 | AM35: 0 | AN35: 其他 | AO35: 0 | AP35: 0 | AQ35: 其他 | AR35: 0 | AS35: 1 | AT35: TOP1 | AU35: 1 | AV35: 0 | AW35: 其他 | AX35: 0 | AY35: 1 | AZ35: TOP2 | BA35: 1 | BB35: 0 | BC35: 0 | BD35: 0 | BE35: 1 | BF35: 0 | BG35: 1 | BH35: 1 | BI35: 3 | BJ35: 是 | BK35: 非主城区 | BL35: 街边店
A36: 海南省 | B36: 东方市 | C36: 东方市 | D36: 大田镇 | E36: 已存在 | F36: CNSCN128701 | G36: 东方大田辰意电信专营店 | H36: 55014111 | I36: CNSQCN00054156 | J36: 综合卖场 | K36: =SUM(T36:AI36) -> 55 | M36: 营业中 | N36: 排它-电信 | O36: 纪定勇 | P36: 17396466123 | Q36: 海南省万宁市万城镇红荣村委会砚田村11队 | R36: 100080562601 | S36: 东方大田辰意电信专营店 | T36: 25 | U36: 3 | V36: 0 | W36: 2 | X36: 0 | Y36: 3 | Z36: 9 | AA36: 0 | AB36: 13 | AC36: 0 | AD36: 0 | AE36: 0 | AF36: 0 | AG36: 0 | AH36: 0 | AI36: 0 | AJ36: 1 | AK36: 其他 | AL36: 0 | AM36: 1 | AN36: 其他 | AO36: 0 | AP36: 1 | AQ36: 其他 | AR36: 0 | AS36: 0 | AT36: 其他 | AU36: 0 | AV36: 0 | AW36: 其他 | AX36: 0 | AY36: 0 | AZ36: 其他 | BA36: 0 | BB36: 0 | BC36: 0 | BD36: 0 | BE36: 0 | BF36: 0 | BG36: 0 | BH36: 1 | BI36: 1 | BJ36: 是 | BK36: 非主城区 | BL36: 街边店
A37: 海南省 | B37: 东方市 | C37: 东方市 | D37: 新龙镇 | E37: 洽谈中 | F37: CNSCN128672 | G37: 东方华侨中国移动东侨达壮营业厅 | H37: 55014116 | I37: CNSQCN00054161 | J37: 综合卖场 | K37: =SUM(T37:AI37) -> 71 | M37: 营业中 | N37: 排它-移动 | O37: 黄硕 | P37: 13976138622 | Q37: 海南省东方市华侨农场 | R37: 200001146301 | S37: 东方华侨经济区侨达手机通讯店 | T37: 33 | U37: 4 | V37: 0 | W37: 2 | X37: 0 | Y37: 10 | Z37: 12 | AA37: 0 | AB37: 10 | AC37: 0 | AD37: 0 | AE37: 0 | AF37: 0 | AG37: 0 | AH37: 0 | AI37: 0 | AJ37: 1 | AK37: 其他 | AL37: 0 | AM37: 1 | AN37: 其他 | AO37: 1 | AP37: 1 | AQ37: 其他 | AR37: 0 | AS37: 0 | AT37: 其他 | AU37: 0 | AV37: 0 | AW37: 其他 | AX37: 0 | AY37: 0 | AZ37: 其他 | BA37: 0 | BB37: 0 | BC37: 0 | BD37: 0 | BE37: 0 | BF37: 0 | BG37: 0 | BH37: 1 | BI37: 1 | BJ37: 是 | BK37: 非主城区 | BL37: 街边店
A38: 海南省 | B38: 东方市 | C38: 东方市 | D38: 八所镇 | E38: 已存在 | F38: CNSCN128670 | G38: 东方市江边移动手机专营店 | H38: 55014109 | I38: CNSQCN00054154 | J38: 综合卖场 | K38: =SUM(T38:AI38) -> 39 | M38: 营业中 | N38: 排它-移动 | O38: 符家政 | P38: 18898933308 | Q38: 海南省东方市江边乡医院旁边 | R38: 100044934901 | S38: 东方市江边移动手机专营店 | T38: 21 | U38: 1 | V38: 0 | W38: 4 | X38: 1 | Y38: 3 | Z38: 2 | AA38: 2 | AB38: 5 | AC38: 0 | AD38: 0 | AE38: 0 | AF38: 0 | AG38: 0 | AH38: 0 | AI38: 0 | AJ38: 1 | AK38: 其他 | AL38: 0 | AM38: 1 | AN38: 其他 | AO38: 0 | AP38: 1 | AQ38: 其他 | AR38: 0 | AS38: 0 | AT38: 其他 | AU38: 0 | AV38: 0 | AW38: 其他 | AX38: 0 | AY38: 0 | AZ38: 其他 | BA38: 0 | BB38: 0 | BC38: 0 | BD38: 0 | BE38: 0 | BF38: 0 | BG38: 0 | BH38: 1 | BI38: 1 | BJ38: 是 | BK38: 非主城区 | BL38: 街边店
A39: 海南省 | B39: 东方市 | C39: 东方市 | D39: 八所镇 | F39: CNSCN128669 | G39: 东方八所强国强正源移动专营店 | H39: 55014109 | I39: CNSQCN00054839 | K39: =SUM(T39:AI39) -> 0 | M39: 闭店 | O39: 谢飞 | P39: 18889498555 | Q39: 海南省东方市东海路三角公园对面正源手机店 | R39: 100024619501 | S39: 东方东海正源通讯店
A40: 海南省 | B40: 东方市 | C40: 东方市 | D40: 八所镇 | E40: 已存在 | F40: CNSCN128668 | G40: 东方八所东海路宏信店 | H40: 55014109 | I40: CNSQCN00054839 | J40: 综合卖场 | K40: =SUM(T40:AI40) -> 131 | M40: 营业中 | N40: 排它-电信 | O40: 曾祥维 | P40: 15091965551 | Q40: 海南省东方市东海路金岛大厦一楼东方八所东海路宏信店 | R40: 100022518601 | S40: 东方市东海高信手机卖场 | T40: 47 | U40: 18 | V40: 1 | W40: 5 | X40: 0 | Y40: 5 | Z40: 22 | AA40: 0 | AB40: 33 | AC40: 0 | AD40: 0 | AE40: 0 | AF40: 0 | AG40: 0 | AH40: 0 | AI40: 0 | AJ40: 1 | AK40: 其他 | AL40: 0 | AM40: 1 | AN40: 其他 | AO40: 0 | AP40: 1 | AQ40: 其他 | AR40: 0 | AS40: 0 | AT40: 其他 | AU40: 0 | AV40: 0 | AW40: 其他 | AX40: 0 | AY40: 0 | AZ40: 其他 | BA40: 0 | BB40: 0 | BC40: 0 | BD40: 0 | BE40: 1 | BF40: 0 | BG40: 1 | BH40: 2 | BI40: 3 | BJ40: 是 | BK40: 主城区 | BL40: 街边店
...

Sheet 通讯客户沙盘
A1: 位置信息 | E1: 客户基础信息 | U1: 客户门店信息/个 （只填数字即可，不加单位） | AF1: 客户促销员信息/个 （只填数字即可，不加单位） | AO1: 客户手机销量/台 （只填数字即可，不加单位） | BJ1: 客户全场景销量/台 （只填数字即可，不加单位） | BQ1: 其他信息
A2: 省份 | B2: 地市 | C2: 县区 | D2: 乡镇 | E2: 是否跨省份 | F2: 是否跨地市 | G2: Account Name(R) | H2: 渠道编码Channel ID(R) | I2: 客户圈层 | J2: 华为客户属性 | K2: OPPO客户层级 | L2: vivo客户层级 | M2: 小米客户层级 | N2: 运营商属性 | O2: 是否为友商代理商 | P2: 是否有小米/华为车授权 | Q2: 老板姓名 | R2: 老板联系电话 | S2: 操盘手姓名 | T2: 操盘手联系电话 | U2: 客户门店总数量 | V2: 综合门店数 | W2: 有荣耀形象的综合门店数 | X2: 专卖店总数 | Y2: 客户荣耀专卖店总数 | Z2: 客户VIVO专卖店总数 | AA2: 客户OPPO专卖店总数 | AB2: 客户华为专卖店总数 | AC2: 客户小米专卖店总数 | AD2: 客户苹果专卖店总数 | AE2: 客户其他品牌店专卖店总数 | AF2: 促销员总数 | AG2: 自有店员数 | AH2: 厂家促销员 | AI2: 荣耀厂家促销员 | AJ2: VIVO厂家促销员 | AK2: OPPO厂家促销员 | AL2: 华为厂家促销员 | AM2: 小米厂家促销员 | AN2: apple厂家促销员 | AO2: 月均CAPA（总体） | AP2: 月均CAPA（零售） | AQ2: 月均CAPA（分销） | AR2: 0-2500元档位零售容量 | AS2: 2500-4000元档位零售容量 | AT2: >4000元档位零售容量 | AU2: 客户荣耀总体月均零售容量 | AV2: 客户VIVO总体月均零售容量 | AW2: 客户OPPO总体月均零售容量 | AX2: 客户华为总体月均零售容量 | AY2: 客户小米总体月均零售容量 | AZ2: 客户苹果总体月均零售容量 | BA2: 月均CAPA(综合店) | BB2: 月均CAPA(专卖店) | BC2: 荣耀专卖店月均零售容量 | BD2: VIVO专卖店月均零售容量 | BE2: OPPO专卖店月均零售容量 | BF2: 华为专卖店月均零售容量 | BG2: 小米专卖店月均零售容量 | BH2: 苹果专卖店月均零售容量 | BI2: 其他专卖店月均零售容量 | BJ2: 荣耀PC销量 | BK2: 华为PC销量 | BL2: 荣耀平板销量 | BM2: 华为平板销量 | BN2: PC销量 | BO2: 平板销量 | BP2: 手表销量 | BQ2: 当前客户使用何种系统（例如九讯云、管家婆等）
A3: 门店沙盘卷积 | B3: 门店沙盘卷积 | C3: 门店沙盘卷积 | D3: 门店沙盘卷积 | E3: 手工录入 | F3: 手工录入 | G3: 门店沙盘卷积（自动卷积） | H3: 门店沙盘卷积 | I3: 手工录入 | J3: 手工录入 | K3: 手工录入 | L3: 手工录入 | M3: 手工录入 | N3: 手工录入 | O3: 手工录入 | P3: 手工录入 | Q3: 手工录入 | R3: 手工录入 | S3: 手工录入 | T3: 手工录入 | U3: 门店沙盘卷积 | V3: 门店沙盘卷积 | W3: 门店沙盘卷积 | X3: 门店沙盘卷积 | Y3: 门店沙盘卷积 | Z3: 门店沙盘卷积 | AA3: 门店沙盘卷积 | AB3: 门店沙盘卷积 | AC3: 门店沙盘卷积 | AD3: 门店沙盘卷积 | AE3: 门店沙盘卷积 | AF3: 门店沙盘卷积 | AG3: 门店沙盘卷积 | AH3: 门店沙盘卷积 | AI3: 门店沙盘卷积 | AJ3: 门店沙盘卷积 | AK3: 门店沙盘卷积 | AL3: 门店沙盘卷积 | AM3: 门店沙盘卷积 | AN3: 门店沙盘卷积 | AO3: 手工录入 | AP3: 门店沙盘卷积 | AQ3: 手工录入 | AR3: 门店沙盘卷积 | AS3: 门店沙盘卷积 | AT3: 门店沙盘卷积 | AU3: 门店沙盘卷积 | AV3: 门店沙盘卷积 | AW3: 门店沙盘卷积 | AX3: 门店沙盘卷积 | AY3: 门店沙盘卷积 | AZ3: 门店沙盘卷积 | BA3: 门店沙盘卷积 | BB3: 门店沙盘卷积 | BC3: 门店沙盘卷积 | BD3: 门店沙盘卷积 | BE3: 门店沙盘卷积 | BF3: 门店沙盘卷积 | BG3: 门店沙盘卷积 | BH3: 门店沙盘卷积 | BI3: 门店沙盘卷积 | BJ3: 门店沙盘卷积 | BK3: 门店沙盘卷积 | BL3: 门店沙盘卷积 | BM3: 门店沙盘卷积 | BN3: 门店沙盘卷积 | BO3: 门店沙盘卷积 | BP3: 门店沙盘卷积 | BQ3: 手工录入
A4: =IFERROR(_xlfn.XLOOKUP($G4,通讯通路门店!$S$4:$S$993931,通讯通路门店!$A$4:$A$993931,0,0),"") -> 海南省 | B4: =IFERROR(_xlfn.XLOOKUP($G4,通讯通路门店!$S$4:$S$993931,通讯通路门店!$B$4:$B$993931,0,0),"") -> 东方市 | C4: =IFERROR(_xlfn.XLOOKUP($G4,通讯通路门店!$S$4:$S$993931,通讯通路门店!$C$4:$C$993931,0,0),"") -> 东方市 | D4: =IFERROR(_xlfn.XLOOKUP($G4,通讯通路门店!$S$4:$S$993931,通讯通路门店!$D$4:$D$993931,0,0),"") -> 大田镇 | G4: {=_xlfn.UNIQUE(通讯通路门店!S4:S993931)} -> 东方八所巨为手机连锁店 | H4: =IFERROR(_xlfn.XLOOKUP($G4,通讯通路门店!$S$4:$S$993931,通讯通路门店!$R$4:$R$993931,0,0),"") -> 200018297501 | U4: =COUNTIF(通讯通路门店!$S:$S,$G4) -> 3 | V4: =COUNTIFS(通讯通路门店!$S:$S,$G4,通讯通路门店!$J:$J,"综合卖场") -> 3 | W4: =SUMIFS(通讯通路门店!$AJ:$AJ,通讯通路门店!$S:$S,通讯客户沙盘!$G4) -> 2 | X4: =Y4+Z4+AA4+AB4+AC4+AD4+AE4 -> 0 | Y4: =COUNTIFS(通讯通路门店!$S:$S,$G4,通讯通路门店!$J:$J,"荣耀体验店")+COUNTIFS(通讯通路门店!$S:$S,$G4,通讯通路门店!$J:$J,"荣耀授权专卖店") -> 0 | Z4: =COUNTIFS(通讯通路门店!$S:$S,$G4,通讯通路门店!$J:$J,"VIVO体验店") -> 0 | AA4: =COUNTIFS(通讯通路门店!$S:$S,$G4,通讯通路门店!$J:$J,"OPPO体验店") -> 0 | AB4: =COUNTIFS(通讯通路门店!$S:$S,$G4,通讯通路门店!$J:$J,"华为授权体验店")+COUNTIFS(通讯通路门店!$S:$S,$G4,通讯通路门店!$J:$J,"华为堡垒店") -> 0 | AC4: =COUNTIFS(通讯通路门店!$S:$S,$G4,通讯通路门店!$J:$J,"小米体验店") -> 0 | AD4: =COUNTIFS(通讯通路门店!$S:$S,$G4,通讯通路门店!$J:$J,"苹果体验店") -> 0 | AE4: =COUNTIFS(通讯通路门店!$S:$S,$G4,通讯通路门店!$J:$J,"其他品牌专卖店") -> 0 | AF4: =SUMIFS(通讯通路门店!$BI:$BI,通讯通路门店!$S:$S,$G4) -> 5 | AG4: =SUMIFS(通讯通路门店!$BH:$BH,通讯通路门店!$S:$S,$G4) -> 4 | AH4: =AI4+AJ4+AK4+AL4+AM4+AN4 -> 1 | AI4: =SUMIFS(通讯通路门店!$BB:$BB,通讯通路门店!$S:$S,$G4) -> 0 | AJ4: =SUMIFS(通讯通路门店!$BE:$BE,通讯通路门店!$S:$S,$G4) -> 1 | AK4: =SUMIFS(通讯通路门店!$BG:$BG,通讯通路门店!$S:$S,$G4) -> 0 | AL4: =SUMIFS(通讯通路门店!$BC:$BC,通讯通路门店!$S:$S,$G4) -> 0 | AM4: =SUMIFS(通讯通路门店!$BD:$BD,通讯通路门店!$S:$S,$G4) -> 0 | AN4: =SUMIFS(通讯通路门店!$BF:$BF,通讯通路门店!$S:$S,$G4) -> 0 | AO4: =AP4+AQ4 -> 545 | AP4: =SUMIFS(通讯通路门店!$K:$K,通讯通路门店!$S:$S,$G4) -> 545 | AR4: =SUMIFS(通讯通路门店!$T:$T,通讯通路门店!$S:$S,$G4) -> 258 | AS4: =SUMIFS(通讯通路门店!$U:$U,通讯通路门店!$S:$S,$G4) -> 15 | AT4: =SUMIFS(通讯通路门店!$V:$V,通讯通路门店!$S:$S,$G4) -> 0 | AU4: =SUMIFS(通讯通路门店!$W:$W,通讯通路门店!$S:$S,$G4) -> 62 | AV4: =SUMIFS(通讯通路门店!$Z:$Z,通讯通路门店!$S:$S,$G4) -> 122 | AW4: =SUMIFS(通讯通路门店!$AB:$AB,通讯通路门店!$S:$S,$G4) -> 75 | AX4: =SUMIFS(通讯通路门店!$X:$X,通讯通路门店!$S:$S,$G4) -> 0 | AY4: =SUMIFS(通讯通路门店!$Y:$Y,通讯通路门店!$S:$S,$G4) -> 13 | AZ4: =SUMIFS(通讯通路门店!$AA:$AA,通讯通路门店!$S:$S,$G4) -> 0 | BA4: =AP4-BB4 -> 545 | BB4: =BC4+BD4+BE4+BF4+BG4+BH4 -> 0 | BC4: =SUMIFS(通讯通路门店!$W:$W,通讯通路门店!$S:$S,$G4,通讯通路门店!$J:$J,"荣耀体验店")+SUMIFS(通讯通路门店!$W:$W,通讯通路门店!$S:$S,$G4,通讯通路门店!$J:$J,"荣耀授权专卖店") -> 0 | BD4: =SUMIFS(通讯通路门店!$Z:$Z,通讯通路门店!$S:$S,$G4,通讯通路门店!$J:$J,"VIVO体验店") -> 0 | BE4: =SUMIFS(通讯通路门店!$AB:$AB,通讯通路门店!$S:$S,$G4,通讯通路门店!$J:$J,"OPPO体验店") -> 0 | BF4: =SUMIFS(通讯通路门店!$X:$X,通讯通路门店!$S:$S,$G4,通讯通路门店!$J:$J,"华为授权体验店")+SUMIFS(通讯通路门店!$AA:$AA,通讯通路门店!$S:$S,$G4,通讯通路门店!$J:$J,"华为堡垒店") -> 0 | BG4: =SUMIFS(通讯通路门店!$Y:$Y,通讯通路门店!$S:$S,$G4,通讯通路门店!$J:$J,"小米体验店") -> 0 | BH4: =SUMIFS(通讯通路门店!$AA:$AA,通讯通路门店!$S:$S,$G4,通讯通路门店!$J:$J,"苹果体验店") -> 0 | BI4: =SUMIFS(通讯通路门店!$K:$K,通讯通路门店!$S:$S,$G4,通讯通路门店!$J:$J,"其他品牌专卖店") -> 0 | BJ4: =SUMIFS(通讯通路门店!$AC:$AC,通讯通路门店!$S:$S,$G4) -> 0 | BK4: =SUMIFS(通讯通路门店!$AD:$AD,通讯通路门店!$S:$S,$G4) -> 0 | BL4: =SUMIFS(通讯通路门店!$AE:$AE,通讯通路门店!$S:$S,$G4) -> 0 | BM4: =SUMIFS(通讯通路门店!$AF:$AF,通讯通路门店!$S:$S,$G4) -> 0 | BN4: =SUMIFS(通讯通路门店!$AG:$AG,通讯通路门店!$S:$S,$G4) -> 0 | BO4: =SUMIFS(通讯通路门店!$AH:$AH,通讯通路门店!$S:$S,$G4) -> 0 | BP4: =SUMIFS(通讯通路门店!$AI:$AI,通讯通路门店!$S:$S,$G4) -> 0
A5: =IFERROR(_xlfn.XLOOKUP($G5,通讯通路门店!$S$4:$S$993931,通讯通路门店!$A$4:$A$993931,0,0),"") -> 海南省 | B5: =IFERROR(_xlfn.XLOOKUP($G5,通讯通路门店!$S$4:$S$993931,通讯通路门店!$B$4:$B$993931,0,0),"") -> 东方市 | C5: =IFERROR(_xlfn.XLOOKUP($G5,通讯通路门店!$S$4:$S$993931,通讯通路门店!$C$4:$C$993931,0,0),"") -> 东方市 | D5: =IFERROR(_xlfn.XLOOKUP($G5,通讯通路门店!$S$4:$S$993931,通讯通路门店!$D$4:$D$993931,0,0),"") -> 八所镇 | G5: 海南华商智能科技有限公司 | H5: =IFERROR(_xlfn.XLOOKUP($G5,通讯通路门店!$S$4:$S$993931,通讯通路门店!$R$4:$R$993931,0,0),"") -> 200002521201 | U5: =COUNTIF(通讯通路门店!$S:$S,$G5) -> 1 | V5: =COUNTIFS(通讯通路门店!$S:$S,$G5,通讯通路门店!$J:$J,"综合卖场") -> 0 | W5: =SUMIFS(通讯通路门店!$AJ:$AJ,通讯通路门店!$S:$S,通讯客户沙盘!$G5) -> 1 | X5: =Y5+Z5+AA5+AB5+AC5+AD5+AE5 -> 1 | Y5: =COUNTIFS(通讯通路门店!$S:$S,$G5,通讯通路门店!$J:$J,"荣耀体验店")+COUNTIFS(通讯通路门店!$S:$S,$G5,通讯通路门店!$J:$J,"荣耀授权专卖店") -> 1 | Z5: =COUNTIFS(通讯通路门店!$S:$S,$G5,通讯通路门店!$J:$J,"VIVO体验店") -> 0 | AA5: =COUNTIFS(通讯通路门店!$S:$S,$G5,通讯通路门店!$J:$J,"OPPO体验店") -> 0 | AB5: =COUNTIFS(通讯通路门店!$S:$S,$G5,通讯通路门店!$J:$J,"华为授权体验店")+COUNTIFS(通讯通路门店!$S:$S,$G5,通讯通路门店!$J:$J,"华为堡垒店") -> 0 | AC5: =COUNTIFS(通讯通路门店!$S:$S,$G5,通讯通路门店!$J:$J,"小米体验店") -> 0 | AD5: =COUNTIFS(通讯通路门店!$S:$S,$G5,通讯通路门店!$J:$J,"苹果体验店") -> 0 | AE5: =COUNTIFS(通讯通路门店!$S:$S,$G5,通讯通路门店!$J:$J,"其他品牌专卖店") -> 0 | AF5: =SUMIFS(通讯通路门店!$BI:$BI,通讯通路门店!$S:$S,$G5) -> 3 | AG5: =SUMIFS(通讯通路门店!$BH:$BH,通讯通路门店!$S:$S,$G5) -> 3 | AH5: =AI5+AJ5+AK5+AL5+AM5+AN5 -> 0 | AI5: =SUMIFS(通讯通路门店!$BB:$BB,通讯通路门店!$S:$S,$G5) -> 0 | AJ5: =SUMIFS(通讯通路门店!$BE:$BE,通讯通路门店!$S:$S,$G5) -> 0 | AK5: =SUMIFS(通讯通路门店!$BG:$BG,通讯通路门店!$S:$S,$G5) -> 0 | AL5: =SUMIFS(通讯通路门店!$BC:$BC,通讯通路门店!$S:$S,$G5) -> 0 | AM5: =SUMIFS(通讯通路门店!$BD:$BD,通讯通路门店!$S:$S,$G5) -> 0 | AN5: =SUMIFS(通讯通路门店!$BF:$BF,通讯通路门店!$S:$S,$G5) -> 0 | AO5: =AP5+AQ5 -> 145 | AP5: =SUMIFS(通讯通路门店!$K:$K,通讯通路门店!$S:$S,$G5) -> 145 | AR5: =SUMIFS(通讯通路门店!$T:$T,通讯通路门店!$S:$S,$G5) -> 12 | AS5: =SUMIFS(通讯通路门店!$U:$U,通讯通路门店!$S:$S,$G5) -> 35 | AT5: =SUMIFS(通讯通路门店!$V:$V,通讯通路门店!$S:$S,$G5) -> 20 | AU5: =SUMIFS(通讯通路门店!$W:$W,通讯通路门店!$S:$S,$G5) -> 67 | AV5: =SUMIFS(通讯通路门店!$Z:$Z,通讯通路门店!$S:$S,$G5) -> 0 | AW5: =SUMIFS(通讯通路门店!$AB:$AB,通讯通路门店!$S:$S,$G5) -> 0 | AX5: =SUMIFS(通讯通路门店!$X:$X,通讯通路门店!$S:$S,$G5) -> 0 | AY5: =SUMIFS(通讯通路门店!$Y:$Y,通讯通路门店!$S:$S,$G5) -> 0 | AZ5: =SUMIFS(通讯通路门店!$AA:$AA,通讯通路门店!$S:$S,$G5) -> 0 | BA5: =AP5-BB5 -> 78 | BB5: =BC5+BD5+BE5+BF5+BG5+BH5 -> 67 | BC5: =SUMIFS(通讯通路门店!$W:$W,通讯通路门店!$S:$S,$G5,通讯通路门店!$J:$J,"荣耀体验店")+SUMIFS(通讯通路门店!$W:$W,通讯通路门店!$S:$S,$G5,通讯通路门店!$J:$J,"荣耀授权专卖店") -> 67 | BD5: =SUMIFS(通讯通路门店!$Z:$Z,通讯通路门店!$S:$S,$G5,通讯通路门店!$J:$J,"VIVO体验店") -> 0 | BE5: =SUMIFS(通讯通路门店!$AB:$AB,通讯通路门店!$S:$S,$G5,通讯通路门店!$J:$J,"OPPO体验店") -> 0 | BF5: =SUMIFS(通讯通路门店!$X:$X,通讯通路门店!$S:$S,$G5,通讯通路门店!$J:$J,"华为授权体验店")+SUMIFS(通讯通路门店!$AA:$AA,通讯通路门店!$S:$S,$G5,通讯通路门店!$J:$J,"华为堡垒店") -> 0 | BG5: =SUMIFS(通讯通路门店!$Y:$Y,通讯通路门店!$S:$S,$G5,通讯通路门店!$J:$J,"小米体验店") -> 0 | BH5: =SUMIFS(通讯通路门店!$AA:$AA,通讯通路门店!$S:$S,$G5,通讯通路门店!$J:$J,"苹果体验店") -> 0 | BI5: =SUMIFS(通讯通路门店!$K:$K,通讯通路门店!$S:$S,$G5,通讯通路门店!$J:$J,"其他品牌专卖店") -> 0 | BJ5: =SUMIFS(通讯通路门店!$AC:$AC,通讯通路门店!$S:$S,$G5) -> 1 | BK5: =SUMIFS(通讯通路门店!$AD:$AD,通讯通路门店!$S:$S,$G5) -> 0 | BL5: =SUMIFS(通讯通路门店!$AE:$AE,通讯通路门店!$S:$S,$G5) -> 3 | BM5: =SUMIFS(通讯通路门店!$AF:$AF,通讯通路门店!$S:$S,$G5) -> 0 | BN5: =SUMIFS(通讯通路门店!$AG:$AG,通讯通路门店!$S:$S,$G5) -> 1 | BO5: =SUMIFS(通讯通路门店!$AH:$AH,通讯通路门店!$S:$S,$G5) -> 3 | BP5: =SUMIFS(通讯通路门店!$AI:$AI,通讯通路门店!$S:$S,$G5) -> 3
A6: =IFERROR(_xlfn.XLOOKUP($G6,通讯通路门店!$S$4:$S$993931,通讯通路门店!$A$4:$A$993931,0,0),"") -> 海南省 | B6: =IFERROR(_xlfn.XLOOKUP($G6,通讯通路门店!$S$4:$S$993931,通讯通路门店!$B$4:$B$993931,0,0),"") -> 东方市 | C6: =IFERROR(_xlfn.XLOOKUP($G6,通讯通路门店!$S$4:$S$993931,通讯通路门店!$C$4:$C$993931,0,0),"") -> 东方市 | D6: =IFERROR(_xlfn.XLOOKUP($G6,通讯通路门店!$S$4:$S$993931,通讯通路门店!$D$4:$D$993931,0,0),"") -> 东河镇 | G6: 东方东河东信翼电信专营店 | H6: =IFERROR(_xlfn.XLOOKUP($G6,通讯通路门店!$S$4:$S$993931,通讯通路门店!$R$4:$R$993931,0,0),"") -> 100073133701 | U6: =COUNTIF(通讯通路门店!$S:$S,$G6) -> 1 | V6: =COUNTIFS(通讯通路门店!$S:$S,$G6,通讯通路门店!$J:$J,"综合卖场") -> 1 | W6: =SUMIFS(通讯通路门店!$AJ:$AJ,通讯通路门店!$S:$S,通讯客户沙盘!$G6) -> 0 | X6: =Y6+Z6+AA6+AB6+AC6+AD6+AE6 -> 0 | Y6: =COUNTIFS(通讯通路门店!$S:$S,$G6,通讯通路门店!$J:$J,"荣耀体验店")+COUNTIFS(通讯通路门店!$S:$S,$G6,通讯通路门店!$J:$J,"荣耀授权专卖店") -> 0 | Z6: =COUNTIFS(通讯通路门店!$S:$S,$G6,通讯通路门店!$J:$J,"VIVO体验店") -> 0 | AA6: =COUNTIFS(通讯通路门店!$S:$S,$G6,通讯通路门店!$J:$J,"OPPO体验店") -> 0 | AB6: =COUNTIFS(通讯通路门店!$S:$S,$G6,通讯通路门店!$J:$J,"华为授权体验店")+COUNTIFS(通讯通路门店!$S:$S,$G6,通讯通路门店!$J:$J,"华为堡垒店") -> 0 | AC6: =COUNTIFS(通讯通路门店!$S:$S,$G6,通讯通路门店!$J:$J,"小米体验店") -> 0 | AD6: =COUNTIFS(通讯通路门店!$S:$S,$G6,通讯通路门店!$J:$J,"苹果体验店") -> 0 | AE6: =COUNTIFS(通讯通路门店!$S:$S,$G6,通讯通路门店!$J:$J,"其他品牌专卖店") -> 0 | AF6: =SUMIFS(通讯通路门店!$BI:$BI,通讯通路门店!$S:$S,$G6) -> 2 | AG6: =SUMIFS(通讯通路门店!$BH:$BH,通讯通路门店!$S:$S,$G6) -> 2 | AH6: =AI6+AJ6+AK6+AL6+AM6+AN6 -> 0 | AI6: =SUMIFS(通讯通路门店!$BB:$BB,通讯通路门店!$S:$S,$G6) -> 0 | AJ6: =SUMIFS(通讯通路门店!$BE:$BE,通讯通路门店!$S:$S,$G6) -> 0 | AK6: =SUMIFS(通讯通路门店!$BG:$BG,通讯通路门店!$S:$S,$G6) -> 0 | AL6: =SUMIFS(通讯通路门店!$BC:$BC,通讯通路门店!$S:$S,$G6) -> 0 | AM6: =SUMIFS(通讯通路门店!$BD:$BD,通讯通路门店!$S:$S,$G6) -> 0 | AN6: =SUMIFS(通讯通路门店!$BF:$BF,通讯通路门店!$S:$S,$G6) -> 0 | AO6: =AP6+AQ6 -> 59 | AP6: =SUMIFS(通讯通路门店!$K:$K,通讯通路门店!$S:$S,$G6) -> 59 | AR6: =SUMIFS(通讯通路门店!$T:$T,通讯通路门店!$S:$S,$G6) -> 28 | AS6: =SUMIFS(通讯通路门店!$U:$U,通讯通路门店!$S:$S,$G6) -> 2 | AT6: =SUMIFS(通讯通路门店!$V:$V,通讯通路门店!$S:$S,$G6) -> 0 | AU6: =SUMIFS(通讯通路门店!$W:$W,通讯通路门店!$S:$S,$G6) -> 5 | AV6: =SUMIFS(通讯通路门店!$Z:$Z,通讯通路门店!$S:$S,$G6) -> 6 | AW6: =SUMIFS(通讯通路门店!$AB:$AB,通讯通路门店!$S:$S,$G6) -> 15 | AX6: =SUMIFS(通讯通路门店!$X:$X,通讯通路门店!$S:$S,$G6) -> 0 | AY6: =SUMIFS(通讯通路门店!$Y:$Y,通讯通路门店!$S:$S,$G6) -> 3 | AZ6: =SUMIFS(通讯通路门店!$AA:$AA,通讯通路门店!$S:$S,$G6) -> 0 | BA6: =AP6-BB6 -> 59 | BB6: =BC6+BD6+BE6+BF6+BG6+BH6 -> 0 | BC6: =SUMIFS(通讯通路门店!$W:$W,通讯通路门店!$S:$S,$G6,通讯通路门店!$J:$J,"荣耀体验店")+SUMIFS(通讯通路门店!$W:$W,通讯通路门店!$S:$S,$G6,通讯通路门店!$J:$J,"荣耀授权专卖店") -> 0 | BD6: =SUMIFS(通讯通路门店!$Z:$Z,通讯通路门店!$S:$S,$G6,通讯通路门店!$J:$J,"VIVO体验店") -> 0 | BE6: =SUMIFS(通讯通路门店!$AB:$AB,通讯通路门店!$S:$S,$G6,通讯通路门店!$J:$J,"OPPO体验店") -> 0 | BF6: =SUMIFS(通讯通路门店!$X:$X,通讯通路门店!$S:$S,$G6,通讯通路门店!$J:$J,"华为授权体验店")+SUMIFS(通讯通路门店!$AA:$AA,通讯通路门店!$S:$S,$G6,通讯通路门店!$J:$J,"华为堡垒店") -> 0 | BG6: =SUMIFS(通讯通路门店!$Y:$Y,通讯通路门店!$S:$S,$G6,通讯通路门店!$J:$J,"小米体验店") -> 0 | BH6: =SUMIFS(通讯通路门店!$AA:$AA,通讯通路门店!$S:$S,$G6,通讯通路门店!$J:$J,"苹果体验店") -> 0 | BI6: =SUMIFS(通讯通路门店!$K:$K,通讯通路门店!$S:$S,$G6,通讯通路门店!$J:$J,"其他品牌专卖店") -> 0 | BJ6: =SUMIFS(通讯通路门店!$AC:$AC,通讯通路门店!$S:$S,$G6) -> 0 | BK6: =SUMIFS(通讯通路门店!$AD:$AD,通讯通路门店!$S:$S,$G6) -> 0 | BL6: =SUMIFS(通讯通路门店!$AE:$AE,通讯通路门店!$S:$S,$G6) -> 0 | BM6: =SUMIFS(通讯通路门店!$AF:$AF,通讯通路门店!$S:$S,$G6) -> 0 | BN6: =SUMIFS(通讯通路门店!$AG:$AG,通讯通路门店!$S:$S,$G6) -> 0 | BO6: =SUMIFS(通讯通路门店!$AH:$AH,通讯通路门店!$S:$S,$G6) -> 0 | BP6: =SUMIFS(通讯通路门店!$AI:$AI,通讯通路门店!$S:$S,$G6) -> 0
A7: =IFERROR(_xlfn.XLOOKUP($G7,通讯通路门店!$S$4:$S$993931,通讯通路门店!$A$4:$A$993931,0,0),"") -> 海南省 | B7: =IFERROR(_xlfn.XLOOKUP($G7,通讯通路门店!$S$4:$S$993931,通讯通路门店!$B$4:$B$993931,0,0),"") -> 东方市 | C7: =IFERROR(_xlfn.XLOOKUP($G7,通讯通路门店!$S$4:$S$993931,通讯通路门店!$C$4:$C$993931,0,0),"") -> 东方市 | D7: =IFERROR(_xlfn.XLOOKUP($G7,通讯通路门店!$S$4:$S$993931,通讯通路门店!$D$4:$D$993931,0,0),"") -> 八所镇 | G7: 海南金鹏东宜通信工程有限公司 | H7: =IFERROR(_xlfn.XLOOKUP($G7,通讯通路门店!$S$4:$S$993931,通讯通路门店!$R$4:$R$993931,0,0),"") -> 100029648601 | U7: =COUNTIF(通讯通路门店!$S:$S,$G7) -> 1 | V7: =COUNTIFS(通讯通路门店!$S:$S,$G7,通讯通路门店!$J:$J,"综合卖场") -> 0 | W7: =SUMIFS(通讯通路门店!$AJ:$AJ,通讯通路门店!$S:$S,通讯客户沙盘!$G7) -> 1 | X7: =Y7+Z7+AA7+AB7+AC7+AD7+AE7 -> 0 | Y7: =COUNTIFS(通讯通路门店!$S:$S,$G7,通讯通路门店!$J:$J,"荣耀体验店")+COUNTIFS(通讯通路门店!$S:$S,$G7,通讯通路门店!$J:$J,"荣耀授权专卖店") -> 0 | Z7: =COUNTIFS(通讯通路门店!$S:$S,$G7,通讯通路门店!$J:$J,"VIVO体验店") -> 0 | AA7: =COUNTIFS(通讯通路门店!$S:$S,$G7,通讯通路门店!$J:$J,"OPPO体验店") -> 0 | AB7: =COUNTIFS(通讯通路门店!$S:$S,$G7,通讯通路门店!$J:$J,"华为授权体验店")+COUNTIFS(通讯通路门店!$S:$S,$G7,通讯通路门店!$J:$J,"华为堡垒店") -> 0 | AC7: =COUNTIFS(通讯通路门店!$S:$S,$G7,通讯通路门店!$J:$J,"小米体验店") -> 0 | AD7: =COUNTIFS(通讯通路门店!$S:$S,$G7,通讯通路门店!$J:$J,"苹果体验店") -> 0 | AE7: =COUNTIFS(通讯通路门店!$S:$S,$G7,通讯通路门店!$J:$J,"其他品牌专卖店") -> 0 | AF7: =SUMIFS(通讯通路门店!$BI:$BI,通讯通路门店!$S:$S,$G7) -> 7 | AG7: =SUMIFS(通讯通路门店!$BH:$BH,通讯通路门店!$S:$S,$G7) -> 6 | AH7: =AI7+AJ7+AK7+AL7+AM7+AN7 -> 1 | AI7: =SUMIFS(通讯通路门店!$BB:$BB,通讯通路门店!$S:$S,$G7) -> 0 | AJ7: =SUMIFS(通讯通路门店!$BE:$BE,通讯通路门店!$S:$S,$G7) -> 0 | AK7: =SUMIFS(通讯通路门店!$BG:$BG,通讯通路门店!$S:$S,$G7) -> 1 | AL7: =SUMIFS(通讯通路门店!$BC:$BC,通讯通路门店!$S:$S,$G7) -> 0 | AM7: =SUMIFS(通讯通路门店!$BD:$BD,通讯通路门店!$S:$S,$G7) -> 0 | AN7: =SUMIFS(通讯通路门店!$BF:$BF,通讯通路门店!$S:$S,$G7) -> 0 | AO7: =AP7+AQ7 -> 248 | AP7: =SUMIFS(通讯通路门店!$K:$K,通讯通路门店!$S:$S,$G7) -> 248 | AR7: =SUMIFS(通讯通路门店!$T:$T,通讯通路门店!$S:$S,$G7) -> 60 | AS7: =SUMIFS(通讯通路门店!$U:$U,通讯通路门店!$S:$S,$G7) -> 76 | AT7: =SUMIFS(通讯通路门店!$V:$V,通讯通路门店!$S:$S,$G7) -> 5 | AU7: =SUMIFS(通讯通路门店!$W:$W,通讯通路门店!$S:$S,$G7) -> 53 | AV7: =SUMIFS(通讯通路门店!$Z:$Z,通讯通路门店!$S:$S,$G7) -> 12 | AW7: =SUMIFS(通讯通路门店!$AB:$AB,通讯通路门店!$S:$S,$G7) -> 7 | AX7: =SUMIFS(通讯通路门店!$X:$X,通讯通路门店!$S:$S,$G7) -> 35 | AY7: =SUMIFS(通讯通路门店!$Y:$Y,通讯通路门店!$S:$S,$G7) -> 0 | AZ7: =SUMIFS(通讯通路门店!$AA:$AA,通讯通路门店!$S:$S,$G7) -> 0 | BA7: =AP7-BB7 -> 248 | BB7: =BC7+BD7+BE7+BF7+BG7+BH7 -> 0 | BC7: =SUMIFS(通讯通路门店!$W:$W,通讯通路门店!$S:$S,$G7,通讯通路门店!$J:$J,"荣耀体验店")+SUMIFS(通讯通路门店!$W:$W,通讯通路门店!$S:$S,$G7,通讯通路门店!$J:$J,"荣耀授权专卖店") -> 0 | BD7: =SUMIFS(通讯通路门店!$Z:$Z,通讯通路门店!$S:$S,$G7,通讯通路门店!$J:$J,"VIVO体验店") -> 0 | BE7: =SUMIFS(通讯通路门店!$AB:$AB,通讯通路门店!$S:$S,$G7,通讯通路门店!$J:$J,"OPPO体验店") -> 0 | BF7: =SUMIFS(通讯通路门店!$X:$X,通讯通路门店!$S:$S,$G7,通讯通路门店!$J:$J,"华为授权体验店")+SUMIFS(通讯通路门店!$AA:$AA,通讯通路门店!$S:$S,$G7,通讯通路门店!$J:$J,"华为堡垒店") -> 0 | BG7: =SUMIFS(通讯通路门店!$Y:$Y,通讯通路门店!$S:$S,$G7,通讯通路门店!$J:$J,"小米体验店") -> 0 | BH7: =SUMIFS(通讯通路门店!$AA:$AA,通讯通路门店!$S:$S,$G7,通讯通路门店!$J:$J,"苹果体验店") -> 0 | BI7: =SUMIFS(通讯通路门店!$K:$K,通讯通路门店!$S:$S,$G7,通讯通路门店!$J:$J,"其他品牌专卖店") -> 0 | BJ7: =SUMIFS(通讯通路门店!$AC:$AC,通讯通路门店!$S:$S,$G7) -> 0 | BK7: =SUMIFS(通讯通路门店!$AD:$AD,通讯通路门店!$S:$S,$G7) -> 0 | BL7: =SUMIFS(通讯通路门店!$AE:$AE,通讯通路门店!$S:$S,$G7) -> 0 | BM7: =SUMIFS(通讯通路门店!$AF:$AF,通讯通路门店!$S:$S,$G7) -> 0 | BN7: =SUMIFS(通讯通路门店!$AG:$AG,通讯通路门店!$S:$S,$G7) -> 0 | BO7: =SUMIFS(通讯通路门店!$AH:$AH,通讯通路门店!$S:$S,$G7) -> 0 | BP7: =SUMIFS(通讯通路门店!$AI:$AI,通讯通路门店!$S:$S,$G7) -> 0
A8: =IFERROR(_xlfn.XLOOKUP($G8,通讯通路门店!$S$4:$S$993931,通讯通路门店!$A$4:$A$993931,0,0),"") -> 海南省 | B8: =IFERROR(_xlfn.XLOOKUP($G8,通讯通路门店!$S$4:$S$993931,通讯通路门店!$B$4:$B$993931,0,0),"") -> 东方市 | C8: =IFERROR(_xlfn.XLOOKUP($G8,通讯通路门店!$S$4:$S$993931,通讯通路门店!$C$4:$C$993931,0,0),"") -> 东方市 | D8: =IFERROR(_xlfn.XLOOKUP($G8,通讯通路门店!$S$4:$S$993931,通讯通路门店!$D$4:$D$993931,0,0),"") -> 八所镇 | G8: 东方八所快捷通信店 | H8: =IFERROR(_xlfn.XLOOKUP($G8,通讯通路门店!$S$4:$S$993931,通讯通路门店!$R$4:$R$993931,0,0),"") -> 100060492301 | U8: =COUNTIF(通讯通路门店!$S:$S,$G8) -> 1 | V8: =COUNTIFS(通讯通路门店!$S:$S,$G8,通讯通路门店!$J:$J,"综合卖场") -> 0 | W8: =SUMIFS(通讯通路门店!$AJ:$AJ,通讯通路门店!$S:$S,通讯客户沙盘!$G8) -> 1 | X8: =Y8+Z8+AA8+AB8+AC8+AD8+AE8 -> 0 | Y8: =COUNTIFS(通讯通路门店!$S:$S,$G8,通讯通路门店!$J:$J,"荣耀体验店")+COUNTIFS(通讯通路门店!$S:$S,$G8,通讯通路门店!$J:$J,"荣耀授权专卖店") -> 0 | Z8: =COUNTIFS(通讯通路门店!$S:$S,$G8,通讯通路门店!$J:$J,"VIVO体验店") -> 0 | AA8: =COUNTIFS(通讯通路门店!$S:$S,$G8,通讯通路门店!$J:$J,"OPPO体验店") -> 0 | AB8: =COUNTIFS(通讯通路门店!$S:$S,$G8,通讯通路门店!$J:$J,"华为授权体验店")+COUNTIFS(通讯通路门店!$S:$S,$G8,通讯通路门店!$J:$J,"华为堡垒店") -> 0 | AC8: =COUNTIFS(通讯通路门店!$S:$S,$G8,通讯通路门店!$J:$J,"小米体验店") -> 0 | AD8: =COUNTIFS(通讯通路门店!$S:$S,$G8,通讯通路门店!$J:$J,"苹果体验店") -> 0 | AE8: =COUNTIFS(通讯通路门店!$S:$S,$G8,通讯通路门店!$J:$J,"其他品牌专卖店") -> 0 | AF8: =SUMIFS(通讯通路门店!$BI:$BI,通讯通路门店!$S:$S,$G8) -> 4 | AG8: =SUMIFS(通讯通路门店!$BH:$BH,通讯通路门店!$S:$S,$G8) -> 3 | AH8: =AI8+AJ8+AK8+AL8+AM8+AN8 -> 1 | AI8: =SUMIFS(通讯通路门店!$BB:$BB,通讯通路门店!$S:$S,$G8) -> 0 | AJ8: =SUMIFS(通讯通路门店!$BE:$BE,通讯通路门店!$S:$S,$G8) -> 1 | AK8: =SUMIFS(通讯通路门店!$BG:$BG,通讯通路门店!$S:$S,$G8) -> 0 | AL8: =SUMIFS(通讯通路门店!$BC:$BC,通讯通路门店!$S:$S,$G8) -> 0 | AM8: =SUMIFS(通讯通路门店!$BD:$BD,通讯通路门店!$S:$S,$G8) -> 0 | AN8: =SUMIFS(通讯通路门店!$BF:$BF,通讯通路门店!$S:$S,$G8) -> 0 | AO8: =AP8+AQ8 -> 104 | AP8: =SUMIFS(通讯通路门店!$K:$K,通讯通路门店!$S:$S,$G8) -> 104 | AR8: =SUMIFS(通讯通路门店!$T:$T,通讯通路门店!$S:$S,$G8) -> 34 | AS8: =SUMIFS(通讯通路门店!$U:$U,通讯通路门店!$S:$S,$G8) -> 17 | AT8: =SUMIFS(通讯通路门店!$V:$V,通讯通路门店!$S:$S,$G8) -> 1 | AU8: =SUMIFS(通讯通路门店!$W:$W,通讯通路门店!$S:$S,$G8) -> 5 | AV8: =SUMIFS(通讯通路门店!$Z:$Z,通讯通路门店!$S:$S,$G8) -> 25 | AW8: =SUMIFS(通讯通路门店!$AB:$AB,通讯通路门店!$S:$S,$G8) -> 20 | AX8: =SUMIFS(通讯通路门店!$X:$X,通讯通路门店!$S:$S,$G8) -> 0 | AY8: =SUMIFS(通讯通路门店!$Y:$Y,通讯通路门店!$S:$S,$G8) -> 0 | AZ8: =SUMIFS(通讯通路门店!$AA:$AA,通讯通路门店!$S:$S,$G8) -> 2 | BA8: =AP8-BB8 -> 104 | BB8: =BC8+BD8+BE8+BF8+BG8+BH8 -> 0 | BC8: =SUMIFS(通讯通路门店!$W:$W,通讯通路门店!$S:$S,$G8,通讯通路门店!$J:$J,"荣耀体验店")+SUMIFS(通讯通路门店!$W:$W,通讯通路门店!$S:$S,$G8,通讯通路门店!$J:$J,"荣耀授权专卖店") -> 0 | BD8: =SUMIFS(通讯通路门店!$Z:$Z,通讯通路门店!$S:$S,$G8,通讯通路门店!$J:$J,"VIVO体验店") -> 0 | BE8: =SUMIFS(通讯通路门店!$AB:$AB,通讯通路门店!$S:$S,$G8,通讯通路门店!$J:$J,"OPPO体验店") -> 0 | BF8: =SUMIFS(通讯通路门店!$X:$X,通讯通路门店!$S:$S,$G8,通讯通路门店!$J:$J,"华为授权体验店")+SUMIFS(通讯通路门店!$AA:$AA,通讯通路门店!$S:$S,$G8,通讯通路门店!$J:$J,"华为堡垒店") -> 0 | BG8: =SUMIFS(通讯通路门店!$Y:$Y,通讯通路门店!$S:$S,$G8,通讯通路门店!$J:$J,"小米体验店") -> 0 | BH8: =SUMIFS(通讯通路门店!$AA:$AA,通讯通路门店!$S:$S,$G8,通讯通路门店!$J:$J,"苹果体验店") -> 0 | BI8: =SUMIFS(通讯通路门店!$K:$K,通讯通路门店!$S:$S,$G8,通讯通路门店!$J:$J,"其他品牌专卖店") -> 0 | BJ8: =SUMIFS(通讯通路门店!$AC:$AC,通讯通路门店!$S:$S,$G8) -> 0 | BK8: =SUMIFS(通讯通路门店!$AD:$AD,通讯通路门店!$S:$S,$G8) -> 0 | BL8: =SUMIFS(通讯通路门店!$AE:$AE,通讯通路门店!$S:$S,$G8) -> 0 | BM8: =SUMIFS(通讯通路门店!$AF:$AF,通讯通路门店!$S:$S,$G8) -> 0 | BN8: =SUMIFS(通讯通路门店!$AG:$AG,通讯通路门店!$S:$S,$G8) -> 0 | BO8: =SUMIFS(通讯通路门店!$AH:$AH,通讯通路门店!$S:$S,$G8) -> 0 | BP8: =SUMIFS(通讯通路门店!$AI:$AI,通讯通路门店!$S:$S,$G8) -> 0
A9: =IFERROR(_xlfn.XLOOKUP($G9,通讯通路门店!$S$4:$S$993931,通讯通路门店!$A$4:$A$993931,0,0),"") -> 海南省 | B9: =IFERROR(_xlfn.XLOOKUP($G9,通讯通路门店!$S$4:$S$993931,通讯通路门店!$B$4:$B$993931,0,0),"") -> 东方市 | C9: =IFERROR(_xlfn.XLOOKUP($G9,通讯通路门店!$S$4:$S$993931,通讯通路门店!$C$4:$C$993931,0,0),"") -> 东方市 | D9: =IFERROR(_xlfn.XLOOKUP($G9,通讯通路门店!$S$4:$S$993931,通讯通路门店!$D$4:$D$993931,0,0),"") -> 八所镇 | G9: 东方八所兴达数码城 | H9: =IFERROR(_xlfn.XLOOKUP($G9,通讯通路门店!$S$4:$S$993931,通讯通路门店!$R$4:$R$993931,0,0),"") -> 100032170201 | U9: =COUNTIF(通讯通路门店!$S:$S,$G9) -> 7 | V9: =COUNTIFS(通讯通路门店!$S:$S,$G9,通讯通路门店!$J:$J,"综合卖场") -> 5 | W9: =SUMIFS(通讯通路门店!$AJ:$AJ,通讯通路门店!$S:$S,通讯客户沙盘!$G9) -> 5 | X9: =Y9+Z9+AA9+AB9+AC9+AD9+AE9 -> 0 | Y9: =COUNTIFS(通讯通路门店!$S:$S,$G9,通讯通路门店!$J:$J,"荣耀体验店")+COUNTIFS(通讯通路门店!$S:$S,$G9,通讯通路门店!$J:$J,"荣耀授权专卖店") -> 0 | Z9: =COUNTIFS(通讯通路门店!$S:$S,$G9,通讯通路门店!$J:$J,"VIVO体验店") -> 0 | AA9: =COUNTIFS(通讯通路门店!$S:$S,$G9,通讯通路门店!$J:$J,"OPPO体验店") -> 0 | AB9: =COUNTIFS(通讯通路门店!$S:$S,$G9,通讯通路门店!$J:$J,"华为授权体验店")+COUNTIFS(通讯通路门店!$S:$S,$G9,通讯通路门店!$J:$J,"华为堡垒店") -> 0 | AC9: =COUNTIFS(通讯通路门店!$S:$S,$G9,通讯通路门店!$J:$J,"小米体验店") -> 0 | AD9: =COUNTIFS(通讯通路门店!$S:$S,$G9,通讯通路门店!$J:$J,"苹果体验店") -> 0 | AE9: =COUNTIFS(通讯通路门店!$S:$S,$G9,通讯通路门店!$J:$J,"其他品牌专卖店") -> 0 | AF9: =SUMIFS(通讯通路门店!$BI:$BI,通讯通路门店!$S:$S,$G9) -> 19 | AG9: =SUMIFS(通讯通路门店!$BH:$BH,通讯通路门店!$S:$S,$G9) -> 14 | AH9: =AI9+AJ9+AK9+AL9+AM9+AN9 -> 7 | AI9: =SUMIFS(通讯通路门店!$BB:$BB,通讯通路门店!$S:$S,$G9) -> 0 | AJ9: =SUMIFS(通讯通路门店!$BE:$BE,通讯通路门店!$S:$S,$G9) -> 3 | AK9: =SUMIFS(通讯通路门店!$BG:$BG,通讯通路门店!$S:$S,$G9) -> 3 | AL9: =SUMIFS(通讯通路门店!$BC:$BC,通讯通路门店!$S:$S,$G9) -> 1 | AM9: =SUMIFS(通讯通路门店!$BD:$BD,通讯通路门店!$S:$S,$G9) -> 0 | AN9: =SUMIFS(通讯通路门店!$BF:$BF,通讯通路门店!$S:$S,$G9) -> 0 | AO9: =AP9+AQ9 -> 674 | AP9: =SUMIFS(通讯通路门店!$K:$K,通讯通路门店!$S:$S,$G9) -> 674 | AR9: =SUMIFS(通讯通路门店!$T:$T,通讯通路门店!$S:$S,$G9) -> 209 | AS9: =SUMIFS(通讯通路门店!$U:$U,通讯通路门店!$S:$S,$G9) -> 106 | AT9: =SUMIFS(通讯通路门店!$V:$V,通讯通路门店!$S:$S,$G9) -> 11 | AU9: =SUMIFS(通讯通路门店!$W:$W,通讯通路门店!$S:$S,$G9) -> 71 | AV9: =SUMIFS(通讯通路门店!$Z:$Z,通讯通路门店!$S:$S,$G9) -> 83 | AW9: =SUMIFS(通讯通路门店!$AB:$AB,通讯通路门店!$S:$S,$G9) -> 117 | AX9: =SUMIFS(通讯通路门店!$X:$X,通讯通路门店!$S:$S,$G9) -> 33 | AY9: =SUMIFS(通讯通路门店!$Y:$Y,通讯通路门店!$S:$S,$G9) -> 20 | AZ9: =SUMIFS(通讯通路门店!$AA:$AA,通讯通路门店!$S:$S,$G9) -> 7 | BA9: =AP9-BB9 -> 674 | BB9: =BC9+BD9+BE9+BF9+BG9+BH9 -> 0 | BC9: =SUMIFS(通讯通路门店!$W:$W,通讯通路门店!$S:$S,$G9,通讯通路门店!$J:$J,"荣耀体验店")+SUMIFS(通讯通路门店!$W:$W,通讯通路门店!$S:$S,$G9,通讯通路门店!$J:$J,"荣耀授权专卖店") -> 0 | BD9: =SUMIFS(通讯通路门店!$Z:$Z,通讯通路门店!$S:$S,$G9,通讯通路门店!$J:$J,"VIVO体验店") -> 0 | BE9: =SUMIFS(通讯通路门店!$AB:$AB,通讯通路门店!$S:$S,$G9,通讯通路门店!$J:$J,"OPPO体验店") -> 0 | BF9: =SUMIFS(通讯通路门店!$X:$X,通讯通路门店!$S:$S,$G9,通讯通路门店!$J:$J,"华为授权体验店")+SUMIFS(通讯通路门店!$AA:$AA,通讯通路门店!$S:$S,$G9,通讯通路门店!$J:$J,"华为堡垒店") -> 0 | BG9: =SUMIFS(通讯通路门店!$Y:$Y,通讯通路门店!$S:$S,$G9,通讯通路门店!$J:$J,"小米体验店") -> 0 | BH9: =SUMIFS(通讯通路门店!$AA:$AA,通讯通路门店!$S:$S,$G9,通讯通路门店!$J:$J,"苹果体验店") -> 0 | BI9: =SUMIFS(通讯通路门店!$K:$K,通讯通路门店!$S:$S,$G9,通讯通路门店!$J:$J,"其他品牌专卖店") -> 0 | BJ9: =SUMIFS(通讯通路门店!$AC:$AC,通讯通路门店!$S:$S,$G9) -> 0 | BK9: =SUMIFS(通讯通路门店!$AD:$AD,通讯通路门店!$S:$S,$G9) -> 1 | BL9: =SUMIFS(通讯通路门店!$AE:$AE,通讯通路门店!$S:$S,$G9) -> 3 | BM9: =SUMIFS(通讯通路门店!$AF:$AF,通讯通路门店!$S:$S,$G9) -> 4 | BN9: =SUMIFS(通讯通路门店!$AG:$AG,通讯通路门店!$S:$S,$G9) -> 1 | BO9: =SUMIFS(通讯通路门店!$AH:$AH,通讯通路门店!$S:$S,$G9) -> 7 | BP9: =SUMIFS(通讯通路门店!$AI:$AI,通讯通路门店!$S:$S,$G9) -> 1
A10: =IFERROR(_xlfn.XLOOKUP($G10,通讯通路门店!$S$4:$S$993931,通讯通路门店!$A$4:$A$993931,0,0),"") -> 海南省 | B10: =IFERROR(_xlfn.XLOOKUP($G10,通讯通路门店!$S$4:$S$993931,通讯通路门店!$B$4:$B$993931,0,0),"") -> 东方市 | C10: =IFERROR(_xlfn.XLOOKUP($G10,通讯通路门店!$S$4:$S$993931,通讯通路门店!$C$4:$C$993931,0,0),"") -> 东方市 | D10: =IFERROR(_xlfn.XLOOKUP($G10,通讯通路门店!$S$4:$S$993931,通讯通路门店!$D$4:$D$993931,0,0),"") -> 八所镇 | G10: 东方八所老客数码产品店 | H10: =IFERROR(_xlfn.XLOOKUP($G10,通讯通路门店!$S$4:$S$993931,通讯通路门店!$R$4:$R$993931,0,0),"") -> 200020610801 | U10: =COUNTIF(通讯通路门店!$S:$S,$G10) -> 1 | V10: =COUNTIFS(通讯通路门店!$S:$S,$G10,通讯通路门店!$J:$J,"综合卖场") -> 1 | W10: =SUMIFS(通讯通路门店!$AJ:$AJ,通讯通路门店!$S:$S,通讯客户沙盘!$G10) -> 1 | X10: =Y10+Z10+AA10+AB10+AC10+AD10+AE10 -> 0 | Y10: =COUNTIFS(通讯通路门店!$S:$S,$G10,通讯通路门店!$J:$J,"荣耀体验店")+COUNTIFS(通讯通路门店!$S:$S,$G10,通讯通路门店!$J:$J,"荣耀授权专卖店") -> 0 | Z10: =COUNTIFS(通讯通路门店!$S:$S,$G10,通讯通路门店!$J:$J,"VIVO体验店") -> 0 | AA10: =COUNTIFS(通讯通路门店!$S:$S,$G10,通讯通路门店!$J:$J,"OPPO体验店") -> 0 | AB10: =COUNTIFS(通讯通路门店!$S:$S,$G10,通讯通路门店!$J:$J,"华为授权体验店")+COUNTIFS(通讯通路门店!$S:$S,$G10,通讯通路门店!$J:$J,"华为堡垒店") -> 0 | AC10: =COUNTIFS(通讯通路门店!$S:$S,$G10,通讯通路门店!$J:$J,"小米体验店") -> 0 | AD10: =COUNTIFS(通讯通路门店!$S:$S,$G10,通讯通路门店!$J:$J,"苹果体验店") -> 0 | AE10: =COUNTIFS(通讯通路门店!$S:$S,$G10,通讯通路门店!$J:$J,"其他品牌专卖店") -> 0 | AF10: =SUMIFS(通讯通路门店!$BI:$BI,通讯通路门店!$S:$S,$G10) -> 3 | AG10: =SUMIFS(通讯通路门店!$BH:$BH,通讯通路门店!$S:$S,$G10) -> 3 | AH10: =AI10+AJ10+AK10+AL10+AM10+AN10 -> 0 | AI10: =SUMIFS(通讯通路门店!$BB:$BB,通讯通路门店!$S:$S,$G10) -> 0 | AJ10: =SUMIFS(通讯通路门店!$BE:$BE,通讯通路门店!$S:$S,$G10) -> 0 | AK10: =SUMIFS(通讯通路门店!$BG:$BG,通讯通路门店!$S:$S,$G10) -> 0 | AL10: =SUMIFS(通讯通路门店!$BC:$BC,通讯通路门店!$S:$S,$G10) -> 0 | AM10: =SUMIFS(通讯通路门店!$BD:$BD,通讯通路门店!$S:$S,$G10) -> 0 | AN10: =SUMIFS(通讯通路门店!$BF:$BF,通讯通路门店!$S:$S,$G10) -> 0 | AO10: =AP10+AQ10 -> 112 | AP10: =SUMIFS(通讯通路门店!$K:$K,通讯通路门店!$S:$S,$G10) -> 112 | AR10: =SUMIFS(通讯通路门店!$T:$T,通讯通路门店!$S:$S,$G10) -> 35 | AS10: =SUMIFS(通讯通路门店!$U:$U,通讯通路门店!$S:$S,$G10) -> 24 | AT10: =SUMIFS(通讯通路门店!$V:$V,通讯通路门店!$S:$S,$G10) -> 0 | AU10: =SUMIFS(通讯通路门店!$W:$W,通讯通路门店!$S:$S,$G10) -> 16 | AV10: =SUMIFS(通讯通路门店!$Z:$Z,通讯通路门店!$S:$S,$G10) -> 11 | AW10: =SUMIFS(通讯通路门店!$AB:$AB,通讯通路门店!$S:$S,$G10) -> 0 | AX10: =SUMIFS(通讯通路门店!$X:$X,通讯通路门店!$S:$S,$G10) -> 9 | AY10: =SUMIFS(通讯通路门店!$Y:$Y,通讯通路门店!$S:$S,$G10) -> 15 | AZ10: =SUMIFS(通讯通路门店!$AA:$AA,通讯通路门店!$S:$S,$G10) -> 2 | BA10: =AP10-BB10 -> 112 | BB10: =BC10+BD10+BE10+BF10+BG10+BH10 -> 0 | BC10: =SUMIFS(通讯通路门店!$W:$W,通讯通路门店!$S:$S,$G10,通讯通路门店!$J:$J,"荣耀体验店")+SUMIFS(通讯通路门店!$W:$W,通讯通路门店!$S:$S,$G10,通讯通路门店!$J:$J,"荣耀授权专卖店") -> 0 | BD10: =SUMIFS(通讯通路门店!$Z:$Z,通讯通路门店!$S:$S,$G10,通讯通路门店!$J:$J,"VIVO体验店") -> 0 | BE10: =SUMIFS(通讯通路门店!$AB:$AB,通讯通路门店!$S:$S,$G10,通讯通路门店!$J:$J,"OPPO体验店") -> 0 | BF10: =SUMIFS(通讯通路门店!$X:$X,通讯通路门店!$S:$S,$G10,通讯通路门店!$J:$J,"华为授权体验店")+SUMIFS(通讯通路门店!$AA:$AA,通讯通路门店!$S:$S,$G10,通讯通路门店!$J:$J,"华为堡垒店") -> 0 | BG10: =SUMIFS(通讯通路门店!$Y:$Y,通讯通路门店!$S:$S,$G10,通讯通路门店!$J:$J,"小米体验店") -> 0 | BH10: =SUMIFS(通讯通路门店!$AA:$AA,通讯通路门店!$S:$S,$G10,通讯通路门店!$J:$J,"苹果体验店") -> 0 | BI10: =SUMIFS(通讯通路门店!$K:$K,通讯通路门店!$S:$S,$G10,通讯通路门店!$J:$J,"其他品牌专卖店") -> 0 | BJ10: =SUMIFS(通讯通路门店!$AC:$AC,通讯通路门店!$S:$S,$G10) -> 0 | BK10: =SUMIFS(通讯通路门店!$AD:$AD,通讯通路门店!$S:$S,$G10) -> 0 | BL10: =SUMIFS(通讯通路门店!$AE:$AE,通讯通路门店!$S:$S,$G10) -> 0 | BM10: =SUMIFS(通讯通路门店!$AF:$AF,通讯通路门店!$S:$S,$G10) -> 0 | BN10: =SUMIFS(通讯通路门店!$AG:$AG,通讯通路门店!$S:$S,$G10) -> 0 | BO10: =SUMIFS(通讯通路门店!$AH:$AH,通讯通路门店!$S:$S,$G10) -> 0 | BP10: =SUMIFS(通讯通路门店!$AI:$AI,通讯通路门店!$S:$S,$G10) -> 0
A11: =IFERROR(_xlfn.XLOOKUP($G11,通讯通路门店!$S$4:$S$993931,通讯通路门店!$A$4:$A$993931,0,0),"") -> 海南省 | B11: =IFERROR(_xlfn.XLOOKUP($G11,通讯通路门店!$S$4:$S$993931,通讯通路门店!$B$4:$B$993931,0,0),"") -> 东方市 | C11: =IFERROR(_xlfn.XLOOKUP($G11,通讯通路门店!$S$4:$S$993931,通讯通路门店!$C$4:$C$993931,0,0),"") -> 东方市 | D11: =IFERROR(_xlfn.XLOOKUP($G11,通讯通路门店!$S$4:$S$993931,通讯通路门店!$D$4:$D$993931,0,0),"") -> 八所镇 | G11: 儋州恒雁通信有限公司 | H11: =IFERROR(_xlfn.XLOOKUP($G11,通讯通路门店!$S$4:$S$993931,通讯通路门店!$R$4:$R$993931,0,0),"") -> 100084347601 | U11: =COUNTIF(通讯通路门店!$S:$S,$G11) -> 1 | V11: =COUNTIFS(通讯通路门店!$S:$S,$G11,通讯通路门店!$J:$J,"综合卖场") -> 1 | W11: =SUMIFS(通讯通路门店!$AJ:$AJ,通讯通路门店!$S:$S,通讯客户沙盘!$G11) -> 1 | X11: =Y11+Z11+AA11+AB11+AC11+AD11+AE11 -> 0 | Y11: =COUNTIFS(通讯通路门店!$S:$S,$G11,通讯通路门店!$J:$J,"荣耀体验店")+COUNTIFS(通讯通路门店!$S:$S,$G11,通讯通路门店!$J:$J,"荣耀授权专卖店") -> 0 | Z11: =COUNTIFS(通讯通路门店!$S:$S,$G11,通讯通路门店!$J:$J,"VIVO体验店") -> 0 | AA11: =COUNTIFS(通讯通路门店!$S:$S,$G11,通讯通路门店!$J:$J,"OPPO体验店") -> 0 | AB11: =COUNTIFS(通讯通路门店!$S:$S,$G11,通讯通路门店!$J:$J,"华为授权体验店")+COUNTIFS(通讯通路门店!$S:$S,$G11,通讯通路门店!$J:$J,"华为堡垒店") -> 0 | AC11: =COUNTIFS(通讯通路门店!$S:$S,$G11,通讯通路门店!$J:$J,"小米体验店") -> 0 | AD11: =COUNTIFS(通讯通路门店!$S:$S,$G11,通讯通路门店!$J:$J,"苹果体验店") -> 0 | AE11: =COUNTIFS(通讯通路门店!$S:$S,$G11,通讯通路门店!$J:$J,"其他品牌专卖店") -> 0 | AF11: =SUMIFS(通讯通路门店!$BI:$BI,通讯通路门店!$S:$S,$G11) -> 4 | AG11: =SUMIFS(通讯通路门店!$BH:$BH,通讯通路门店!$S:$S,$G11) -> 4 | AH11: =AI11+AJ11+AK11+AL11+AM11+AN11 -> 0 | AI11: =SUMIFS(通讯通路门店!$BB:$BB,通讯通路门店!$S:$S,$G11) -> 0 | AJ11: =SUMIFS(通讯通路门店!$BE:$BE,通讯通路门店!$S:$S,$G11) -> 0 | AK11: =SUMIFS(通讯通路门店!$BG:$BG,通讯通路门店!$S:$S,$G11) -> 0 | AL11: =SUMIFS(通讯通路门店!$BC:$BC,通讯通路门店!$S:$S,$G11) -> 0 | AM11: =SUMIFS(通讯通路门店!$BD:$BD,通讯通路门店!$S:$S,$G11) -> 0 | AN11: =SUMIFS(通讯通路门店!$BF:$BF,通讯通路门店!$S:$S,$G11) -> 0 | AO11: =AP11+AQ11 -> 104 | AP11: =SUMIFS(通讯通路门店!$K:$K,通讯通路门店!$S:$S,$G11) -> 104 | AR11: =SUMIFS(通讯通路门店!$T:$T,通讯通路门店!$S:$S,$G11) -> 51 | AS11: =SUMIFS(通讯通路门店!$U:$U,通讯通路门店!$S:$S,$G11) -> 4 | AT11: =SUMIFS(通讯通路门店!$V:$V,通讯通路门店!$S:$S,$G11) -> 0 | AU11: =SUMIFS(通讯通路门店!$W:$W,通讯通路门店!$S:$S,$G11) -> 5 | AV11: =SUMIFS(通讯通路门店!$Z:$Z,通讯通路门店!$S:$S,$G11) -> 12 | AW11: =SUMIFS(通讯通路门店!$AB:$AB,通讯通路门店!$S:$S,$G11) -> 22 | AX11: =SUMIFS(通讯通路门店!$X:$X,通讯通路门店!$S:$S,$G11) -> 0 | AY11: =SUMIFS(通讯通路门店!$Y:$Y,通讯通路门店!$S:$S,$G11) -> 10 | AZ11: =SUMIFS(通讯通路门店!$AA:$AA,通讯通路门店!$S:$S,$G11) -> 0 | BA11: =AP11-BB11 -> 104 | BB11: =BC11+BD11+BE11+BF11+BG11+BH11 -> 0 | BC11: =SUMIFS(通讯通路门店!$W:$W,通讯通路门店!$S:$S,$G11,通讯通路门店!$J:$J,"荣耀体验店")+SUMIFS(通讯通路门店!$W:$W,通讯通路门店!$S:$S,$G11,通讯通路门店!$J:$J,"荣耀授权专卖店") -> 0 | BD11: =SUMIFS(通讯通路门店!$Z:$Z,通讯通路门店!$S:$S,$G11,通讯通路门店!$J:$J,"VIVO体验店") -> 0 | BE11: =SUMIFS(通讯通路门店!$AB:$AB,通讯通路门店!$S:$S,$G11,通讯通路门店!$J:$J,"OPPO体验店") -> 0 | BF11: =SUMIFS(通讯通路门店!$X:$X,通讯通路门店!$S:$S,$G11,通讯通路门店!$J:$J,"华为授权体验店")+SUMIFS(通讯通路门店!$AA:$AA,通讯通路门店!$S:$S,$G11,通讯通路门店!$J:$J,"华为堡垒店") -> 0 | BG11: =SUMIFS(通讯通路门店!$Y:$Y,通讯通路门店!$S:$S,$G11,通讯通路门店!$J:$J,"小米体验店") -> 0 | BH11: =SUMIFS(通讯通路门店!$AA:$AA,通讯通路门店!$S:$S,$G11,通讯通路门店!$J:$J,"苹果体验店") -> 0 | BI11: =SUMIFS(通讯通路门店!$K:$K,通讯通路门店!$S:$S,$G11,通讯通路门店!$J:$J,"其他品牌专卖店") -> 0 | BJ11: =SUMIFS(通讯通路门店!$AC:$AC,通讯通路门店!$S:$S,$G11) -> 0 | BK11: =SUMIFS(通讯通路门店!$AD:$AD,通讯通路门店!$S:$S,$G11) -> 0 | BL11: =SUMIFS(通讯通路门店!$AE:$AE,通讯通路门店!$S:$S,$G11) -> 0 | BM11: =SUMIFS(通讯通路门店!$AF:$AF,通讯通路门店!$S:$S,$G11) -> 0 | BN11: =SUMIFS(通讯通路门店!$AG:$AG,通讯通路门店!$S:$S,$G11) -> 0 | BO11: =SUMIFS(通讯通路门店!$AH:$AH,通讯通路门店!$S:$S,$G11) -> 0 | BP11: =SUMIFS(通讯通路门店!$AI:$AI,通讯通路门店!$S:$S,$G11) -> 0
